Workbook

Sheet 00-三表与联动
A1: MU · Micron Technology, Inc. —— 三表与联动
A2: 单位：百万美元 | 财年截止约每年 8 月底/9 月初 | 数据源：公司 FY26 Q1/Q2/Q3 财报原文 + FY26 Q4 官方指引 | Q3 止于 2026-05-28
A4: 00 公司速览与估值锚点
A5: 项目 | B5: 数值 | D5: 口径与说明
A6: 现价（2026-08-24 收盘） | B6: 903.09 | D6: 当日区间 $887.61–$942.52。52 周区间 $114.25–$1,255.00。★ 本格可改
A7: 市值 | B7: 1018685 | D7: ＝ 现价 × 基本股数，已突破 1 万亿美元
A8: 基本股数（百万股） | B8: 1128 | D8: FY26 Q3 基本加权股数
A9: 摊薄股数（百万股） | B9: 1150 | D9: 公司 FY26 Q4 指引「约 11.5 亿摊薄股」
A10: 现金及可交易投资 | B10: 30155 | D10: 现金 24,995 + 短期投资 1,027 + 长期可交易投资 4,106 + 受限现金 27
A11: 有息负债 | B11: 5722 | D11: 一年内到期 582 + 长期 5,140。已从 FY25 末的 14,577 降至 5,722
A12: 净现金 | B12: =B10-B11 -> 24433 | D12: ＝ 现金及投资 − 有息负债。MU 为净现金结构
A13: 季度股息（美元/股） | B13: 0.15 | D13: 年化 $0.60。CHIPS 协议对回购有限制，2026-12-09 后放开
A14: 无风险利率 Rf | B14: 0.042 | D14: 10 年期美国国债收益率
A15: 股权风险溢价 ERP | B15: 0.05 | D15: 美国成熟市场长期股权风险溢价
A16: 01 三情形估值对比（数字实时链接自后面三张 DCF 表）
A17: 情形 | B17: 每股内在价值 | C17: 相对现价 | D17: 终值占 EV | E17: FY27 收入 | F17: FY27 毛利率 | G17: FY32 毛利率 | H17: WACC | I17: 永续 g | J17: 一句话论点
A18: 悲观 | B18: ='01-DCF-悲观'!B72 -> 282.16108 | C18: ='01-DCF-悲观'!B74 -> -0.6875604 | D18: ='01-DCF-悲观'!B65 -> 0.46946174 | E18: ='01-DCF-悲观'!F13 -> 176999.93 | F18: ='01-DCF-悲观'!F15 -> 0.73401133 | G18: ='01-DCF-悲观'!G34 -> 0.43 | H18: ='01-DCF-悲观'!$B$211 -> 0.13 | I18: ='01-DCF-悲观'!$B$213 -> 0.025 | J18: DRAM 随 NAND 在 2027 年转向，而自建厂的资本开支是刚性的
A19: 基准 | B19: ='02-DCF-基准'!B72 -> 1081.8568 | C19: ='02-DCF-基准'!B74 -> 0.19795015 | D19: ='02-DCF-基准'!B65 -> 0.64257993 | E19: ='02-DCF-基准'!F13 -> 205000.09 | F19: ='02-DCF-基准'!F15 -> 0.82656096 | G19: ='02-DCF-基准'!G34 -> 0.68 | H19: ='02-DCF-基准'!$B$211 -> 0.11 | I19: ='02-DCF-基准'!$B$213 -> 0.03 | J19: FY27 见顶但不崩塌；MU 的 DRAM 权重使其下行风险小于纯 NAND 标的
A20: 乐观 | B20: ='03-DCF-乐观'!B72 -> 2640.66 | C20: ='03-DCF-乐观'!B74 -> 1.9240275 | D20: ='03-DCF-乐观'!B65 -> 0.72534669 | E20: ='03-DCF-乐观'!F13 -> 243000 | F20: ='03-DCF-乐观'!F15 -> 0.86615226 | G20: ='03-DCF-乐观'!G34 -> 0.74 | H20: ='03-DCF-乐观'!$B$211 -> 0.095 | I20: ='03-DCF-乐观'!$B$213 -> 0.035 | J20: SCA 照付不议合约把存储从周期股变成合约制生意
A21: 当前股价（2026-08-24） | B21: 903.09 | C21: 52 周区间 $114.25 – $1,255.00。过去一年涨约 700%，市值突破 1 万亿美元
A22: 卖方一致目标价 | B22: 1515 | C22: S&P Global 汇总 47 家机构，评级「强烈买入」；最低 $361、最高 $2,200。这个 6 倍的区间跨度本身就说明分歧极大
A23: ★ 读这张表之前必须知道的三件事：① MU 与纯 NAND 标的（如 SNDK）最根本的不同是自建晶圆厂——FY25 资本开支占收入 36.9%，FY26 约 20.9%，绝对额从 $138 亿升到约 $270 亿，管理层已指引 FY27 继续上升。收入下行时资本开支不会同步下行，这是存储自建厂商现金流崩塌的机制；② MU 约 76% 收入来自 DRAM（FY26 Q3 DRAM 收入 $313 亿），而《缺口的算术》的结论是 NAND 先于 DRAM 转过剩——这构成 MU 相对纯 NAND 标的的结构性优势，也是本模型三个情形分歧的核心；③ FY26 Q4 尚未披露（财年止于 2026-09-03），本表该列为公司官方指引，未指引的利息与税项按注明假设填列。
A25: 02 合并利润表（季度 + 年度）
A26: 科目（百万美元） | B26: FY26 Q1 | C26: FY26 Q2 | D26: FY26 Q3 | E26: FY26 Q4E （指引） | F26: FY2026E | G26: FY2025 | H26: Q4E 环比 | I26: FY26E 同比 | J26: 备注
A27: 营业收入 Revenue | B27: 13643 | C27: 23860 | D27: 41456 | E27: 50000 | F27: 128959 | G27: 37382 | H27: =IF(D27=0,"n/a",E27/ABS(D27)-1) -> 0.20609803 | I27: =IF(G27=0,"n/a",F27/ABS(G27)-1) -> 2.4497619
A28: 营业成本 Cost of goods sold | B28: 5997 | C28: 6105 | D28: 6400 | E28: 7000 | F28: 25502 | G28: 22363 | H28: =IF(D28=0,"n/a",E28/ABS(D28)-1) -> 0.09375 | I28: =IF(G28=0,"n/a",F28/ABS(G28)-1) -> 0.14036578
A29: 毛利 Gross margin | B29: 7646 | C29: 17755 | D29: 35056 | E29: 43000 | F29: 103457 | G29: 15019 | H29: =IF(D29=0,"n/a",E29/ABS(D29)-1) -> 0.22660885 | I29: =IF(G29=0,"n/a",F29/ABS(G29)-1) -> 5.888408
A30: 研发费用 R&D | B30: 1171 | C30: 1250 | D30: 1316 | E30: 1408 | F30: 5145 | G30: 3951 | H30: =IF(D30=0,"n/a",E30/ABS(D30)-1) -> 0.069908815 | I30: =IF(G30=0,"n/a",F30/ABS(G30)-1) -> 0.30220197
A31: 销售管理费用 SG&A | B31: 337 | C31: 344 | D31: 407 | E31: 436 | F31: 1524 | G31: 1195 | H31: =IF(D31=0,"n/a",E31/ABS(D31)-1) -> 0.071253071 | I31: =IF(G31=0,"n/a",F31/ABS(G31)-1) -> 0.27531381
A32: 其他营业(收入)费用净额 Other opex | B32: 2 | C32: 26 | D32: 15 | E32: 16 | F32: 59 | G32: -243 | H32: =IF(D32=0,"n/a",E32/ABS(D32)-1) -> 0.066666667 | I32: =IF(G32=0,"n/a",F32/ABS(G32)-1) -> -0.75720165
A33: 营业费用合计 Total opex | B33: 1510 | C33: 1620 | D33: 1738 | E33: 1860 | F33: 6728 | G33: 4903 | H33: =IF(D33=0,"n/a",E33/ABS(D33)-1) -> 0.070195627 | I33: =IF(G33=0,"n/a",F33/ABS(G33)-1) -> 0.37222109
A34: 营业利润 Operating income | B34: 6136 | C34: 16135 | D34: 33318 | E34: 41140 | F34: 96729 | G34: 10116 | H34: =IF(D34=0,"n/a",E34/ABS(D34)-1) -> 0.23476799 | I34: =IF(G34=0,"n/a",F34/ABS(G34)-1) -> 8.561981
A35: 利息收入 Interest income | B35: 139 | C35: 155 | D35: 215 | E35: 300 | F35: 809 | G35: 485 | H35: =IF(D35=0,"n/a",E35/ABS(D35)-1) -> 0.39534884 | I35: =IF(G35=0,"n/a",F35/ABS(G35)-1) -> 0.66804124
A36: 利息支出 Interest expense | B36: -74 | C36: -32 | D36: 0 | E36: 0 | F36: -106 | G36: -476 | H36: =IF(D36=0,"n/a",E36/ABS(D36)-1) -> n/a | I36: =IF(G36=0,"n/a",F36/ABS(G36)-1) -> -1.2226891
A37: 其他非经营损益 Other non-operating | B37: -140 | C37: -98 | D37: -321 | E37: -100 | F37: -659 | G37: -145 | H37: =IF(D37=0,"n/a",E37/ABS(D37)-1) -> -1.3115265 | I37: =IF(G37=0,"n/a",F37/ABS(G37)-1) -> -5.5448276
A38: 税前利润 Income before taxes | B38: 6061 | C38: 16160 | D38: 33212 | E38: 41340 | F38: 96773 | G38: 9980 | H38: =IF(D38=0,"n/a",E38/ABS(D38)-1) -> 0.24473082 | I38: =IF(G38=0,"n/a",F38/ABS(G38)-1) -> 8.6966934
... A41: 净利润 Net income | B41: 5240 | C41: 13785 | D41: 28243 | E41: 35340 | F41: 82608 | G41: 8540 | H41: =IF(D41=0,"n/a",E41/ABS(D41)-1) -> 0.2512835 | I41: =IF(G41=0,"n/a",F41/ABS(G41)-1) -> 8.6730679
A42: 毛利率 Gross margin | B42: =B29/B27 -> 0.56043392 | C42: =C29/C27 -> 0.74413244 | D42: =D29/D27 -> 0.84561945 | E42: =E29/E27 -> 0.86 | F42: =F29/F27 -> 0.80224723 | G42: =G29/G27 -> 0.40177091
A43: 营业利润率 Operating margin | B43: =B34/B27 -> 0.44975445 | C43: =C34/C27 -> 0.67623638 | D43: =D34/D27 -> 0.80369548 | E43: =E34/E27 -> 0.8228 | F43: =F34/F27 -> 0.75007561 | G43: =G34/G27 -> 0.27061152
A44: 净利率 Net margin | B44: =B41/B27 -> 0.38407975 | C44: =C41/C27 -> 0.57774518 | D44: =D41/D27 -> 0.68127653 | E44: =E41/E27 -> 0.7068 | F44: =F41/F27 -> 0.64057569 | G44: =G41/G27 -> 0.2284522
...

Sheet 01-DCF-悲观
A1: BEAR · MU 现金流折现模型 —— 悲观情形
A2: FY2027 分四个季度 → FY2028–FY2032 按年 → 永续 | 自由现金流口径：FCFF（资本开支扣除 CHIPS 补贴后） | ▼ 全部参数由本表底部的参数控制台滑标驱动
A4: 00 本情形的论点：这套数字建立在什么判断之上
A5: 承接《缺口的算术》：NAND 在 2027 年先转过剩，DRAM 随后跟上。SCA 虽锁定约 20% 的 DRAM 量与三分之一的 NAND 量，但意味着还有约 80% 的 DRAM 敞口在合约价重定价时无保护。本情形假设合约价在 FY27 下半年见顶回落，FY28 出现典型的存储下行周期——而 MU 的固定成本（FY26 资本开支约 $270 亿、折旧摊销约 $94 亿）在下行年不会同步缩减。
A6: 1．FY27 下半年 DRAM 合约价环比转负，Q4 收入回到 $330 亿（约为 FY26 Q4 指引的 66%）
A7: 2．FY28 收入 −35%、毛利率回到 38%——接近 MU FY2025 的 40.2%，即「超级周期之前的正常年份」
A8: 3．★ 资本开支的刚性是 MU 与 SNDK 最大的不同：收入腰斩时资本开支率会被动飙到 23% 以上
A9: 4．WACC 用 13%（周期底部风险溢价上升），永续增长 2.5%
A11: 01 FY2027 季度预测（先用季度把最近的可见度做实，再转年度）
A12: 科目（百万美元） | B12: FY27 Q1 | C12: FY27 Q2 | D12: FY27 Q3 | E12: FY27 Q4 | F12: FY2027 合计 | G12: 变量怎么来的
A13: 营业收入 | B13: =$B$189 -> 52000 | C13: =B13*(1+-0.038462+$B$191) -> 49999.976 | D13: =C13*(1+-0.16+$B$191) -> 41999.98 | E13: =D13*(1+-0.214286+$B$191) -> 32999.972 | F13: =SUM(B13:E13) -> 176999.93 | G13: Q1 ＝ 控制台滑标（官方指引 $10.3–10.8B）；Q2–Q4 ＝ 上一季 ×(1 + 情形环比增速 + 滑标平移)
A14: 环比增速 QoQ | B14: =B13/'00-三表与联动'!E27-1 -> 0.04 | C14: =C13/B13-1 -> -0.038462 | D14: =D13/C13-1 -> -0.16 | E14: =E13/D13-1 -> -0.214286 | F14: =F13/'00-三表与联动'!F27-1 -> 0.3725287 | G14: Q1 的环比基数是 FY26 Q4 的 $8,965M（不是 FY26 全年）；Q2–Q4 为上一季
A15: 毛利率 | B15: =MAX(0.05,MIN(0.92,0.85+$B$193)) -> 0.85 | C15: =MAX(0.05,MIN(0.92,0.8+$B$193)) -> 0.8 | D15: =MAX(0.05,MIN(0.92,0.68+$B$193)) -> 0.68 | E15: =MAX(0.05,MIN(0.92,0.52+$B$193)) -> 0.52 | F15: =F16/F13 -> 0.73401133 | G15: 情形设定的季度毛利率路径 + 控制台「毛利率平移」，上下限锁在 5%–92%
A16: 毛利 | B16: =B13*B15 -> 44200 | C16: =C13*C15 -> 39999.981 | D16: =D13*D15 -> 28559.986 | E16: =E13*E15 -> 17159.986 | F16: =SUM(B16:E16) -> 129919.95 | G16: ＝ 收入 × 毛利率
A17: 营业费用 | B17: =B13*$B$199 -> 2860 | C17: =C13*$B$199 -> 2749.9987 | D17: =D13*$B$199 -> 2309.9989 | E17: =E13*$B$199 -> 1814.9985 | F17: =SUM(B17:E17) -> 9734.996 | G17: ＝ 收入 × 控制台「营业费用率」。公司 FY27 Q1 GAAP 指引为 $574–614M
A18: 营业利润 EBIT | B18: =B16-B17 -> 41340 | C18: =C16-C17 -> 37249.982 | D18: =D16-D17 -> 26249.987 | E18: =E16-E17 -> 15344.987 | F18: =SUM(B18:E18) -> 120184.96 | G18: ＝ 毛利 − 营业费用
A19: 营业利润率 | B19: =B18/B13 -> 0.795 | C19: =C18/C13 -> 0.745 | D19: =D18/D13 -> 0.625 | E19: =E18/E13 -> 0.465 | F19: =F18/F13 -> 0.67901133 | G19: ＝ EBIT ÷ 收入
A20: 所得税 | B20: =MAX(0,B18)*$B$201 -> 7441.2 | C20: =MAX(0,C18)*$B$201 -> 6704.9968 | D20: =MAX(0,D18)*$B$201 -> 4724.9977 | E20: =MAX(0,E18)*$B$201 -> 2762.0977 | F20: =SUM(B20:E20) -> 21633.292 | G20: ＝ EBIT × 控制台「有效税率」（FCFF 口径按 EBIT 计税，不含利息）
A21: 税后经营利润 NOPAT | B21: =B18-B20 -> 33898.8 | C21: =C18-C20 -> 30544.985 | D21: =D18-D20 -> 21524.99 | E21: =E18-E20 -> 12582.889 | F21: =SUM(B21:E21) -> 98551.664 | G21: ＝ EBIT − 所得税
A22: ＋ 折旧摊销 D&A | B22: =B13*$B$207 -> 5460 | C22: =C13*$B$207 -> 5249.9975 | D22: =D13*$B$207 -> 4409.9979 | E22: =E13*$B$207 -> 3464.9971 | F22: =SUM(B22:E22) -> 18584.992 | G22: ＝ 收入 × 控制台「折旧摊销率」。FY26 前九个月 $6,862M，全年约 $94 亿（占收入 7.3%）。★ MU 自建晶圆厂，折旧全部落在自己报表上
A23: − 资本开支（总额） | B23: =-B13*$B$203 -> -11960 | C23: =-C13*$B$203 -> -11499.994 | D23: =-D13*$B$203 -> -9659.9954 | E23: =-E13*$B$203 -> -7589.9936 | F23: =SUM(B23:E23) -> -40709.983 | G23: ＝ 收入 × 控制台「资本开支率」。FY26 约 $270 亿；管理层已指引 FY27 季度资本开支高于 FY26 Q4 的约 $100 亿/季
A24: ＋ CHIPS 政府补贴抵扣 | B24: =-B23*$B$205 -> 1435.2 | C24: =-C23*$B$205 -> 1379.9993 | D24: =-D23*$B$205 -> 1159.1994 | E24: =-E23*$B$205 -> 910.79923 | F24: =SUM(B24:E24) -> 4885.198 | G24: ＝ 资本开支 × 控制台「政府补贴抵扣比例」。FY26 前九个月收到 $2,989M，占同期资本开支 15.2%
A25: 营运资本余额 | B25: =B13*4*$B$209 -> 36400 | C25: =C13*4*$B$209 -> 34999.983 | D25: =D13*4*$B$209 -> 29399.986 | E25: =E13*4*$B$209 -> 23099.981 | F25: =E25 -> 23099.981 | G25: ＝ 控制台「营运资本占年化收入比」× 当季收入 × 4。期初取 FY26 Q4 的年化收入基准
A26: − 营运资本增加 ΔNWC | B26: =-(B25-'00-三表与联动'!E27*4*$B$209) -> -1400 | C26: =-(C25-B25) -> 1400.0168 | D26: =-(D25-C25) -> 5599.9973 | E26: =-(E25-D25) -> 6300.0054 | F26: =SUM(B26:E26) -> 11900.019 | G26: ＝ 本季余额 − 上季余额。余额法，不再用「占收入增量比」
A27: ＝ 自由现金流 FCFF | B27: =B21+B22+B23+B24+B26 -> 27434 | C27: =C21+C22+C23+C24+C26 -> 27075.004 | D27: =D21+D22+D23+D24+D26 -> 23034.189 | E27: =E21+E22+E23+E24+E26 -> 15668.697 | F27: =SUM(B27:E27) -> 93211.891 | G27: ＝ NOPAT + D&A − 资本开支 + 政府补贴 − ΔNWC
A28: 口径说明：这里算的是 FCFF（企业自由现金流），所以税按 EBIT 计、不扣利息——利息的价值已经体现在折现率里。公司目前零负债，FCFF 与 FCFE 的差异只剩利息收入。
A30: 02 FY2028–FY2032 年度预测 + 永续
A31: 科目（百万美元） | B31: FY2027 | C31: FY2028 | D31: FY2029 | E31: FY2030 | F31: FY2031 | G31: FY2032 | H31: 永续期 | I31: 变量怎么来的
A32: 营业收入 | B32: =F13 -> 176999.93 | C32: =B32*(1+-0.35) -> 115049.95 | D32: =C32*(1+-0.08+$B$197) -> 105845.96 | E32: =D32*(1+0.14+$B$197) -> 120664.39 | F32: =E32*(1+0.12+$B$197) -> 135144.12 | G32: =F32*(1+0.08+$B$197) -> 145955.65 | H32: =G32*(1+$B$213) -> 149604.54 | I32: FY27 取季度合计；FY28 ＝ 情形设定增速；FY29–32 ＝ 情形增速 + 控制台「长期增速平移」
A33: 收入增速 YoY | B33: =B32/'00-三表与联动'!F27-1 -> 0.3725287 | C33: =C32/B32-1 -> -0.35 | D33: =D32/C32-1 -> -0.08 | E33: =E32/D32-1 -> 0.14 | F33: =F32/E32-1 -> 0.12 | G33: =G32/F32-1 -> 0.08 | H33: =$B$213 -> 0.025 | I33: 逐年同比。FY26 实际为 +175%
A34: 毛利率 | B34: =F16/F13 -> 0.73401133 | C34: =MAX(0.05,MIN(0.92,0.38+$B$193)) -> 0.38 | D34: =MAX(0.05,MIN(0.92,0.33+$B$193)) -> 0.33 | E34: =MAX(0.05,MIN(0.92,0.4+$B$193)) -> 0.4 | F34: =MAX(0.05,MIN(0.92,0.43+$B$193)) -> 0.43 | G34: =$B$195 -> 0.43 | H34: =G34 -> 0.43 | I34: 情形设定的年度毛利率 + 控制台「毛利率平移」；FY32 直接取控制台「终局毛利率」
A35: 毛利 | B35: =B32*B34 -> 129919.95 | C35: =C32*C34 -> 43718.982 | D35: =D32*D34 -> 34929.166 | E35: =E32*E34 -> 48265.756 | F35: =F32*F34 -> 58111.971 | G35: =G32*G34 -> 62760.928 | H35: =H32*H34 -> 64329.952 | I35: ＝ 收入 × 毛利率
A36: 营业费用 | B36: =B32*$B$199 -> 9734.996 | C36: =C32*$B$199 -> 6327.7474 | D36: =D32*$B$199 -> 5821.5276 | E36: =E32*$B$199 -> 6636.5415 | F36: =F32*$B$199 -> 7432.9265 | G36: =G32*$B$199 -> 8027.5606 | H36: =H32*$B$199 -> 8228.2496 | I36: ＝ 收入 × 控制台「营业费用率」
A37: 营业利润 EBIT | B37: =B35-B36 -> 120184.96 | C37: =C35-C36 -> 37391.235 | D37: =D35-D36 -> 29107.638 | E37: =E35-E36 -> 41629.215 | F37: =F35-F36 -> 50679.044 | G37: =G35-G36 -> 54733.368 | H37: =H35-H36 -> 56101.702 | I37: ＝ 毛利 − 营业费用
A38: 营业利润率 | B38: =B37/B32 -> 0.67901133 | C38: =C37/C32 -> 0.325 | D38: =D37/D32 -> 0.275 | E38: =E37/E32 -> 0.345 | F38: =F37/F32 -> 0.375 | G38: =G37/G32 -> 0.375 | H38: =H37/H32 -> 0.375 | I38: ＝ EBIT ÷ 收入。可与投资者日目标「约 75%」对照
A39: 税后经营利润 NOPAT | B39: =B37*(1-$B$201) -> 98551.664 | C39: =C37*(1-$B$201) -> 30660.813 | D39: =D37*(1-$B$201) -> 23868.263 | E39: =E37*(1-$B$201) -> 34135.956 | F39: =F37*(1-$B$201) -> 41556.816 | G39: =G37*(1-$B$201) -> 44881.362 | H39: =H37*(1-$B$201) -> 46003.396 | I39: ＝ EBIT ×(1 − 有效税率)
A40: ＋ 折旧摊销 D&A | B40: =B32*$B$207 -> 18584.992 | C40: =C32*$B$207 -> 12080.245 | D40: =D32*$B$207 -> 11113.825 | E40: =E32*$B$207 -> 12669.761 | F40: =F32*$B$207 -> 14190.132 | G40: =G32*$B$207 -> 15325.343 | H40: =H32*$B$207 -> 15708.477 | I40: ＝ 收入 × 控制台「折旧摊销率」。★ 折旧跟随资产基数而非收入，收入下行年该比例会被动上升
A41: − 资本开支（总额） | B41: =-B32*$B$203 -> -40709.983 | C41: =-C32*$B$203 -> -26461.489 | D41: =-D32*$B$203 -> -24344.57 | E41: =-E32*$B$203 -> -27752.81 | F41: =-F32*$B$203 -> -31083.147 | G41: =-G32*$B$203 -> -33569.799 | H41: =-H32*$B$203 -> -34409.044 | I41: ＝ 收入 × 控制台「资本开支率」
A42: ＋ CHIPS 政府补贴抵扣 | B42: =-B41*$B$205 -> 4885.198 | C42: =-C41*$B$205 -> 3175.3787 | D42: =-D41*$B$205 -> 2921.3484 | E42: =-E41*$B$205 -> 3330.3372 | F42: =-F41*$B$205 -> 3729.9777 | G42: =-G41*$B$205 -> 4028.3759 | H42: =-H41*$B$205 -> 4129.0853 | I42: ＝ 资本开支 × 控制台「政府补贴抵扣比例」
A43: 营运资本余额 | B43: =B32*$B$209 -> 30974.987 | C43: =C32*$B$209 -> 20133.742 | D43: =D32*$B$209 -> 18523.042 | E43: =E32*$B$209 -> 21116.268 | F43: =F32*$B$209 -> 23650.221 | G43: =G32*$B$209 -> 25542.238 | H43: =H32*$B$209 -> 26180.794 | I43: ＝ 控制台「营运资本占年化收入比」× 当年收入。期初取 FY26 Q4 年化收入 × 同一比例
...

Sheet 02-DCF-基准
A1: BASE · MU 现金流折现模型 —— 基准情形
A2: FY2027 分四个季度 → FY2028–FY2032 按年 → 永续 | 自由现金流口径：FCFF（资本开支扣除 CHIPS 补贴后） | ▼ 全部参数由本表底部的参数控制台滑标驱动
A4: 00 本情形的论点：这套数字建立在什么判断之上
A5: 以公司 FY26 Q4 指引（收入 $500 亿、毛利率约 86%）为起点。管理层称供需紧张将持续到 2027 日历年之后，但本情形不完全接受「周期已被 SCA 消灭」。★ 关键差异：MU 约 76% 收入来自 DRAM，而《缺口的算术》的结论是NAND 在 2027 年转过剩、DRAM 仍然偏紧——这意味着 MU 的下行风险结构性小于纯 NAND 标的。本情形假设 FY27 见顶、FY28 温和回落一年，之后毛利率稳定在 68%–72% 的新中枢。
A6: 1．FY27 Q1 取 $530 亿（较 FY26 Q4 指引 $500 亿环比 +6%），全年 $2,050 亿
A7: 2．FY28 收入 −20%：一次温和的价格修正，而非崩塌；DRAM 的紧张度好于 NAND
A8: 3．★ SCA 覆盖约 20% DRAM 量 + 三分之一 NAND 量、$1,000 亿最低合约收入，构成价格地板但不是全部
A9: 4．终局毛利率 68%，远高于 FY25 的 40.2%，但低于当前的 86%
A11: 01 FY2027 季度预测（先用季度把最近的可见度做实，再转年度）
A12: 科目（百万美元） | B12: FY27 Q1 | C12: FY27 Q2 | D12: FY27 Q3 | E12: FY27 Q4 | F12: FY2027 合计 | G12: 变量怎么来的
A13: 营业收入 | B13: =$B$189 -> 53000 | C13: =B13*(1+0.037736+$B$191) -> 55000.008 | D13: =C13*(1+-0.054545+$B$191) -> 52000.033 | E13: =D13*(1+-0.134615+$B$191) -> 45000.048 | F13: =SUM(B13:E13) -> 205000.09 | G13: Q1 ＝ 控制台滑标（官方指引 $10.3–10.8B）；Q2–Q4 ＝ 上一季 ×(1 + 情形环比增速 + 滑标平移)
A14: 环比增速 QoQ | B14: =B13/'00-三表与联动'!E27-1 -> 0.06 | C14: =C13/B13-1 -> 0.037736 | D14: =D13/C13-1 -> -0.054545 | E14: =E13/D13-1 -> -0.134615 | F14: =F13/'00-三表与联动'!F27-1 -> 0.58965321 | G14: Q1 的环比基数是 FY26 Q4 的 $8,965M（不是 FY26 全年）；Q2–Q4 为上一季
A15: 毛利率 | B15: =MAX(0.05,MIN(0.92,0.86+$B$193)) -> 0.86 | C15: =MAX(0.05,MIN(0.92,0.855+$B$193)) -> 0.855 | D15: =MAX(0.05,MIN(0.92,0.82+$B$193)) -> 0.82 | E15: =MAX(0.05,MIN(0.92,0.76+$B$193)) -> 0.76 | F15: =F16/F13 -> 0.82656096 | G15: 情形设定的季度毛利率路径 + 控制台「毛利率平移」，上下限锁在 5%–92%
A16: 毛利 | B16: =B13*B15 -> 45580 | C16: =C13*C15 -> 47025.007 | D16: =D13*D15 -> 42640.027 | E16: =E13*E15 -> 34200.037 | F16: =SUM(B16:E16) -> 169445.07 | G16: ＝ 收入 × 毛利率
A17: 营业费用 | B17: =B13*$B$199 -> 2226 | C17: =C13*$B$199 -> 2310.0003 | D17: =D13*$B$199 -> 2184.0014 | E17: =E13*$B$199 -> 1890.002 | F17: =SUM(B17:E17) -> 8610.0037 | G17: ＝ 收入 × 控制台「营业费用率」。公司 FY27 Q1 GAAP 指引为 $574–614M
A18: 营业利润 EBIT | B18: =B16-B17 -> 43354 | C18: =C16-C17 -> 44715.007 | D18: =D16-D17 -> 40456.025 | E18: =E16-E17 -> 32310.035 | F18: =SUM(B18:E18) -> 160835.07 | G18: ＝ 毛利 − 营业费用
A19: 营业利润率 | B19: =B18/B13 -> 0.818 | C19: =C18/C13 -> 0.813 | D19: =D18/D13 -> 0.778 | E19: =E18/E13 -> 0.718 | F19: =F18/F13 -> 0.78456096 | G19: ＝ EBIT ÷ 收入
A20: 所得税 | B20: =MAX(0,B18)*$B$201 -> 7153.41 | C20: =MAX(0,C18)*$B$201 -> 7377.9761 | D20: =MAX(0,D18)*$B$201 -> 6675.2442 | E20: =MAX(0,E18)*$B$201 -> 5331.1557 | F20: =SUM(B20:E20) -> 26537.786 | G20: ＝ EBIT × 控制台「有效税率」（FCFF 口径按 EBIT 计税，不含利息）
A21: 税后经营利润 NOPAT | B21: =B18-B20 -> 36200.59 | C21: =C18-C20 -> 37337.03 | D21: =D18-D20 -> 33780.781 | E21: =E18-E20 -> 26978.879 | F21: =SUM(B21:E21) -> 134297.28 | G21: ＝ EBIT − 所得税
A22: ＋ 折旧摊销 D&A | B22: =B13*$B$207 -> 3975 | C22: =C13*$B$207 -> 4125.0006 | D22: =D13*$B$207 -> 3900.0024 | E22: =E13*$B$207 -> 3375.0036 | F22: =SUM(B22:E22) -> 15375.007 | G22: ＝ 收入 × 控制台「折旧摊销率」。FY26 前九个月 $6,862M，全年约 $94 亿（占收入 7.3%）。★ MU 自建晶圆厂，折旧全部落在自己报表上
A23: − 资本开支（总额） | B23: =-B13*$B$203 -> -9540 | C23: =-C13*$B$203 -> -9900.0014 | D23: =-D13*$B$203 -> -9360.0059 | E23: =-E13*$B$203 -> -8100.0087 | F23: =SUM(B23:E23) -> -36900.016 | G23: ＝ 收入 × 控制台「资本开支率」。FY26 约 $270 亿；管理层已指引 FY27 季度资本开支高于 FY26 Q4 的约 $100 亿/季
A24: ＋ CHIPS 政府补贴抵扣 | B24: =-B23*$B$205 -> 954 | C24: =-C23*$B$205 -> 990.00014 | D24: =-D23*$B$205 -> 936.00059 | E24: =-E23*$B$205 -> 810.00087 | F24: =SUM(B24:E24) -> 3690.0016 | G24: ＝ 资本开支 × 控制台「政府补贴抵扣比例」。FY26 前九个月收到 $2,989M，占同期资本开支 15.2%
A25: 营运资本余额 | B25: =B13*4*$B$209 -> 31800 | C25: =C13*4*$B$209 -> 33000.005 | D25: =D13*4*$B$209 -> 31200.02 | E25: =E13*4*$B$209 -> 27000.029 | F25: =E25 -> 27000.029 | G25: ＝ 控制台「营运资本占年化收入比」× 当季收入 × 4。期初取 FY26 Q4 的年化收入基准
A26: − 营运资本增加 ΔNWC | B26: =-(B25-'00-三表与联动'!E27*4*$B$209) -> -1800 | C26: =-(C25-B25) -> -1200.0048 | D26: =-(D25-C25) -> 1799.9853 | E26: =-(E25-D25) -> 4199.9906 | F26: =SUM(B26:E26) -> 2999.9711 | G26: ＝ 本季余额 − 上季余额。余额法，不再用「占收入增量比」
A27: ＝ 自由现金流 FCFF | B27: =B21+B22+B23+B24+B26 -> 29789.59 | C27: =C21+C22+C23+C24+C26 -> 31352.025 | D27: =D21+D22+D23+D24+D26 -> 31056.764 | E27: =E21+E22+E23+E24+E26 -> 27263.865 | F27: =SUM(B27:E27) -> 119462.24 | G27: ＝ NOPAT + D&A − 资本开支 + 政府补贴 − ΔNWC
A28: 口径说明：这里算的是 FCFF（企业自由现金流），所以税按 EBIT 计、不扣利息——利息的价值已经体现在折现率里。公司目前零负债，FCFF 与 FCFE 的差异只剩利息收入。
A30: 02 FY2028–FY2032 年度预测 + 永续
A31: 科目（百万美元） | B31: FY2027 | C31: FY2028 | D31: FY2029 | E31: FY2030 | F31: FY2031 | G31: FY2032 | H31: 永续期 | I31: 变量怎么来的
A32: 营业收入 | B32: =F13 -> 205000.09 | C32: =B32*(1+-0.2) -> 164000.07 | D32: =C32*(1+0.12+$B$197) -> 183680.08 | E32: =D32*(1+0.14+$B$197) -> 209395.29 | F32: =E32*(1+0.12+$B$197) -> 234522.73 | G32: =F32*(1+0.1+$B$197) -> 257975 | H32: =G32*(1+$B$213) -> 265714.25 | I32: FY27 取季度合计；FY28 ＝ 情形设定增速；FY29–32 ＝ 情形增速 + 控制台「长期增速平移」
A33: 收入增速 YoY | B33: =B32/'00-三表与联动'!F27-1 -> 0.58965321 | C33: =C32/B32-1 -> -0.2 | D33: =D32/C32-1 -> 0.12 | E33: =E32/D32-1 -> 0.14 | F33: =F32/E32-1 -> 0.12 | G33: =G32/F32-1 -> 0.1 | H33: =$B$213 -> 0.03 | I33: 逐年同比。FY26 实际为 +175%
A34: 毛利率 | B34: =F16/F13 -> 0.82656096 | C34: =MAX(0.05,MIN(0.92,0.68+$B$193)) -> 0.68 | D34: =MAX(0.05,MIN(0.92,0.7+$B$193)) -> 0.7 | E34: =MAX(0.05,MIN(0.92,0.72+$B$193)) -> 0.72 | F34: =MAX(0.05,MIN(0.92,0.7+$B$193)) -> 0.7 | G34: =$B$195 -> 0.68 | H34: =G34 -> 0.68 | I34: 情形设定的年度毛利率 + 控制台「毛利率平移」；FY32 直接取控制台「终局毛利率」
A35: 毛利 | B35: =B32*B34 -> 169445.07 | C35: =C32*C34 -> 111520.05 | D35: =D32*D34 -> 128576.06 | E35: =E32*E34 -> 150764.61 | F35: =F32*F34 -> 164165.91 | G35: =G32*G34 -> 175423 | H35: =H32*H34 -> 180685.69 | I35: ＝ 收入 × 毛利率
A36: 营业费用 | B36: =B32*$B$199 -> 8610.0037 | C36: =C32*$B$199 -> 6888.003 | D36: =D32*$B$199 -> 7714.5633 | E36: =E32*$B$199 -> 8794.6022 | F36: =F32*$B$199 -> 9849.9545 | G36: =G32*$B$199 -> 10834.95 | H36: =H32*$B$199 -> 11159.998 | I36: ＝ 收入 × 控制台「营业费用率」
A37: 营业利润 EBIT | B37: =B35-B36 -> 160835.07 | C37: =C35-C36 -> 104632.05 | D37: =D35-D36 -> 120861.49 | E37: =E35-E36 -> 141970.01 | F37: =F35-F36 -> 154315.95 | G37: =G35-G36 -> 164588.05 | H37: =H35-H36 -> 169525.69 | I37: ＝ 毛利 − 营业费用
A38: 营业利润率 | B38: =B37/B32 -> 0.78456096 | C38: =C37/C32 -> 0.638 | D38: =D37/D32 -> 0.658 | E38: =E37/E32 -> 0.678 | F38: =F37/F32 -> 0.658 | G38: =G37/G32 -> 0.638 | H38: =H37/H32 -> 0.638 | I38: ＝ EBIT ÷ 收入。可与投资者日目标「约 75%」对照
A39: 税后经营利润 NOPAT | B39: =B37*(1-$B$201) -> 134297.28 | C39: =C37*(1-$B$201) -> 87367.758 | D39: =D37*(1-$B$201) -> 100919.35 | E39: =E37*(1-$B$201) -> 118544.96 | F39: =F37*(1-$B$201) -> 128853.82 | G39: =G37*(1-$B$201) -> 137431.02 | H39: =H37*(1-$B$201) -> 141553.95 | I39: ＝ EBIT ×(1 − 有效税率)
A40: ＋ 折旧摊销 D&A | B40: =B32*$B$207 -> 15375.007 | C40: =C32*$B$207 -> 12300.005 | D40: =D32*$B$207 -> 13776.006 | E40: =E32*$B$207 -> 15704.647 | F40: =F32*$B$207 -> 17589.204 | G40: =G32*$B$207 -> 19348.125 | H40: =H32*$B$207 -> 19928.569 | I40: ＝ 收入 × 控制台「折旧摊销率」。★ 折旧跟随资产基数而非收入，收入下行年该比例会被动上升
A41: − 资本开支（总额） | B41: =-B32*$B$203 -> -36900.016 | C41: =-C32*$B$203 -> -29520.013 | D41: =-D32*$B$203 -> -33062.414 | E41: =-E32*$B$203 -> -37691.152 | F41: =-F32*$B$203 -> -42214.091 | G41: =-G32*$B$203 -> -46435.5 | H41: =-H32*$B$203 -> -47828.565 | I41: ＝ 收入 × 控制台「资本开支率」
A42: ＋ CHIPS 政府补贴抵扣 | B42: =-B41*$B$205 -> 3690.0016 | C42: =-C41*$B$205 -> 2952.0013 | D42: =-D41*$B$205 -> 3306.2414 | E42: =-E41*$B$205 -> 3769.1152 | F42: =-F41*$B$205 -> 4221.4091 | G42: =-G41*$B$205 -> 4643.55 | H42: =-H41*$B$205 -> 4782.8565 | I42: ＝ 资本开支 × 控制台「政府补贴抵扣比例」
A43: 营运资本余额 | B43: =B32*$B$209 -> 30750.013 | C43: =C32*$B$209 -> 24600.011 | D43: =D32*$B$209 -> 27552.012 | E43: =E32*$B$209 -> 31409.294 | F43: =F32*$B$209 -> 35178.409 | G43: =G32*$B$209 -> 38696.25 | H43: =H32*$B$209 -> 39857.137 | I43: ＝ 控制台「营运资本占年化收入比」× 当年收入。期初取 FY26 Q4 年化收入 × 同一比例
...

Sheet 03-DCF-乐观
A1: BULL · MU 现金流折现模型 —— 乐观情形
A2: FY2027 分四个季度 → FY2028–FY2032 按年 → 永续 | 自由现金流口径：FCFF（资本开支扣除 CHIPS 补贴后） | ▼ 全部参数由本表底部的参数控制台滑标驱动
A4: 00 本情形的论点：这套数字建立在什么判断之上
A5: 完全采纳管理层口径：DRAM 与 NAND 供需紧张持续到 2027 日历年之后，HBM3E/HBM4 已售罄至 2027 年，16 份 SCA 带来约 $1,000 亿最低合约收入与 $220 亿客户资金承诺，管理层目标是把一半以上收入纳入 SCA。如果这套「照付不议」的合约体系真的把存储从周期股变成合约制生意，那么当前 6–7 倍的前瞻市盈率是严重错配。
A6: 1．FY27 逐季爬坡至 $660 亿/季，全年 $2,430 亿
A7: 2．FY28–FY30 毛利率维持 78%–82%，对应管理层「紧张持续到 CY2027 之后」的判断
A8: 3．★ SCA 把价格地板锁在 FY26 Q2 水平，下行周期的深度被合约结构截断
A9: 4．WACC 降到 9.5%（现金流可预测性提高），永续增长 3.5%
A11: 01 FY2027 季度预测（先用季度把最近的可见度做实，再转年度）
A12: 科目（百万美元） | B12: FY27 Q1 | C12: FY27 Q2 | D12: FY27 Q3 | E12: FY27 Q4 | F12: FY2027 合计 | G12: 变量怎么来的
A13: 营业收入 | B13: =$B$189 -> 55000 | C13: =B13*(1+0.072727+$B$191) -> 58999.985 | D13: =C13*(1+0.067797+$B$191) -> 63000.007 | E13: =D13*(1+0.047619+$B$191) -> 66000.004 | F13: =SUM(B13:E13) -> 243000 | G13: Q1 ＝ 控制台滑标（官方指引 $10.3–10.8B）；Q2–Q4 ＝ 上一季 ×(1 + 情形环比增速 + 滑标平移)
A14: 环比增速 QoQ | B14: =B13/'00-三表与联动'!E27-1 -> 0.1 | C14: =C13/B13-1 -> 0.072727 | D14: =D13/C13-1 -> 0.067797 | E14: =E13/D13-1 -> 0.047619 | F14: =F13/'00-三表与联动'!F27-1 -> 0.88431979 | G14: Q1 的环比基数是 FY26 Q4 的 $8,965M（不是 FY26 全年）；Q2–Q4 为上一季
A15: 毛利率 | B15: =MAX(0.05,MIN(0.92,0.865+$B$193)) -> 0.865 | C15: =MAX(0.05,MIN(0.92,0.87+$B$193)) -> 0.87 | D15: =MAX(0.05,MIN(0.92,0.87+$B$193)) -> 0.87 | E15: =MAX(0.05,MIN(0.92,0.86+$B$193)) -> 0.86 | F15: =F16/F13 -> 0.86615226 | G15: 情形设定的季度毛利率路径 + 控制台「毛利率平移」，上下限锁在 5%–92%
A16: 毛利 | B16: =B13*B15 -> 47575 | C16: =C13*C15 -> 51329.987 | D16: =D13*D15 -> 54810.006 | E16: =E13*E15 -> 56760.004 | F16: =SUM(B16:E16) -> 210475 | G16: ＝ 收入 × 毛利率
A17: 营业费用 | B17: =B13*$B$199 -> 1925 | C17: =C13*$B$199 -> 2064.9995 | D17: =D13*$B$199 -> 2205.0002 | E17: =E13*$B$199 -> 2310.0002 | F17: =SUM(B17:E17) -> 8504.9999 | G17: ＝ 收入 × 控制台「营业费用率」。公司 FY27 Q1 GAAP 指引为 $574–614M
A18: 营业利润 EBIT | B18: =B16-B17 -> 45650 | C18: =C16-C17 -> 49264.987 | D18: =D16-D17 -> 52605.006 | E18: =E16-E17 -> 54450.004 | F18: =SUM(B18:E18) -> 201970 | G18: ＝ 毛利 − 营业费用
A19: 营业利润率 | B19: =B18/B13 -> 0.83 | C19: =C18/C13 -> 0.835 | D19: =D18/D13 -> 0.835 | E19: =E18/E13 -> 0.825 | F19: =F18/F13 -> 0.83115226 | G19: ＝ EBIT ÷ 收入
A20: 所得税 | B20: =MAX(0,B18)*$B$201 -> 7075.75 | C20: =MAX(0,C18)*$B$201 -> 7636.0731 | D20: =MAX(0,D18)*$B$201 -> 8153.7759 | E20: =MAX(0,E18)*$B$201 -> 8439.7506 | F20: =SUM(B20:E20) -> 31305.35 | G20: ＝ EBIT × 控制台「有效税率」（FCFF 口径按 EBIT 计税，不含利息）
A21: 税后经营利润 NOPAT | B21: =B18-B20 -> 38574.25 | C21: =C18-C20 -> 41628.914 | D21: =D18-D20 -> 44451.23 | E21: =E18-E20 -> 46010.253 | F21: =SUM(B21:E21) -> 170664.65 | G21: ＝ EBIT − 所得税
A22: ＋ 折旧摊销 D&A | B22: =B13*$B$207 -> 3575 | C22: =C13*$B$207 -> 3834.999 | D22: =D13*$B$207 -> 4095.0005 | E22: =E13*$B$207 -> 4290.0003 | F22: =SUM(B22:E22) -> 15795 | G22: ＝ 收入 × 控制台「折旧摊销率」。FY26 前九个月 $6,862M，全年约 $94 亿（占收入 7.3%）。★ MU 自建晶圆厂，折旧全部落在自己报表上
A23: − 资本开支（总额） | B23: =-B13*$B$203 -> -8525 | C23: =-C13*$B$203 -> -9144.9977 | D23: =-D13*$B$203 -> -9765.0011 | E23: =-E13*$B$203 -> -10230.001 | F23: =SUM(B23:E23) -> -37664.999 | G23: ＝ 收入 × 控制台「资本开支率」。FY26 约 $270 亿；管理层已指引 FY27 季度资本开支高于 FY26 Q4 的约 $100 亿/季
A24: ＋ CHIPS 政府补贴抵扣 | B24: =-B23*$B$205 -> 767.25 | C24: =-C23*$B$205 -> 823.04979 | D24: =-D23*$B$205 -> 878.8501 | E24: =-E23*$B$205 -> 920.70006 | F24: =SUM(B24:E24) -> 3389.8499 | G24: ＝ 资本开支 × 控制台「政府补贴抵扣比例」。FY26 前九个月收到 $2,989M，占同期资本开支 15.2%
A25: 营运资本余额 | B25: =B13*4*$B$209 -> 29700 | C25: =C13*4*$B$209 -> 31859.992 | D25: =D13*4*$B$209 -> 34020.004 | E25: =E13*4*$B$209 -> 35640.002 | F25: =E25 -> 35640.002 | G25: ＝ 控制台「营运资本占年化收入比」× 当季收入 × 4。期初取 FY26 Q4 的年化收入基准
A26: − 营运资本增加 ΔNWC | B26: =-(B25-'00-三表与联动'!E27*4*$B$209) -> -2700 | C26: =-(C25-B25) -> -2159.9919 | D26: =-(D25-C25) -> -2160.0119 | E26: =-(E25-D25) -> -1619.9986 | F26: =SUM(B26:E26) -> -8640.0023 | G26: ＝ 本季余额 − 上季余额。余额法，不再用「占收入增量比」
A27: ＝ 自由现金流 FCFF | B27: =B21+B22+B23+B24+B26 -> 31691.5 | C27: =C21+C22+C23+C24+C26 -> 34981.974 | D27: =D21+D22+D23+D24+D26 -> 37500.068 | E27: =E21+E22+E23+E24+E26 -> 39370.954 | F27: =SUM(B27:E27) -> 143544.5 | G27: ＝ NOPAT + D&A − 资本开支 + 政府补贴 − ΔNWC
A28: 口径说明：这里算的是 FCFF（企业自由现金流），所以税按 EBIT 计、不扣利息——利息的价值已经体现在折现率里。公司目前零负债，FCFF 与 FCFE 的差异只剩利息收入。
A30: 02 FY2028–FY2032 年度预测 + 永续
A31: 科目（百万美元） | B31: FY2027 | C31: FY2028 | D31: FY2029 | E31: FY2030 | F31: FY2031 | G31: FY2032 | H31: 永续期 | I31: 变量怎么来的
A32: 营业收入 | B32: =F13 -> 243000 | C32: =B32*(1+0.15) -> 279450 | D32: =C32*(1+0.14+$B$197) -> 318573 | E32: =D32*(1+0.12+$B$197) -> 356801.75 | F32: =E32*(1+0.1+$B$197) -> 392481.93 | G32: =F32*(1+0.08+$B$197) -> 423880.48 | H32: =G32*(1+$B$213) -> 438716.3 | I32: FY27 取季度合计；FY28 ＝ 情形设定增速；FY29–32 ＝ 情形增速 + 控制台「长期增速平移」
A33: 收入增速 YoY | B33: =B32/'00-三表与联动'!F27-1 -> 0.88431979 | C33: =C32/B32-1 -> 0.15 | D33: =D32/C32-1 -> 0.14 | E33: =E32/D32-1 -> 0.12 | F33: =F32/E32-1 -> 0.1 | G33: =G32/F32-1 -> 0.08 | H33: =$B$213 -> 0.035 | I33: 逐年同比。FY26 实际为 +175%
A34: 毛利率 | B34: =F16/F13 -> 0.86615226 | C34: =MAX(0.05,MIN(0.92,0.82+$B$193)) -> 0.82 | D34: =MAX(0.05,MIN(0.92,0.8+$B$193)) -> 0.8 | E34: =MAX(0.05,MIN(0.92,0.78+$B$193)) -> 0.78 | F34: =MAX(0.05,MIN(0.92,0.76+$B$193)) -> 0.76 | G34: =$B$195 -> 0.74 | H34: =G34 -> 0.74 | I34: 情形设定的年度毛利率 + 控制台「毛利率平移」；FY32 直接取控制台「终局毛利率」
A35: 毛利 | B35: =B32*B34 -> 210475 | C35: =C32*C34 -> 229149 | D35: =D32*D34 -> 254858.4 | E35: =E32*E34 -> 278305.37 | F35: =F32*F34 -> 298286.27 | G35: =G32*G34 -> 313671.56 | H35: =H32*H34 -> 324650.06 | I35: ＝ 收入 × 毛利率
A36: 营业费用 | B36: =B32*$B$199 -> 8504.9999 | C36: =C32*$B$199 -> 9780.7499 | D36: =D32*$B$199 -> 11150.055 | E36: =E32*$B$199 -> 12488.061 | F36: =F32*$B$199 -> 13736.868 | G36: =G32*$B$199 -> 14835.817 | H36: =H32*$B$199 -> 15355.071 | I36: ＝ 收入 × 控制台「营业费用率」
A37: 营业利润 EBIT | B37: =B35-B36 -> 201970 | C37: =C35-C36 -> 219368.25 | D37: =D35-D36 -> 243708.34 | E37: =E35-E36 -> 265817.31 | F37: =F35-F36 -> 284549.4 | G37: =G35-G36 -> 298835.74 | H37: =H35-H36 -> 309294.99 | I37: ＝ 毛利 − 营业费用
A38: 营业利润率 | B38: =B37/B32 -> 0.83115226 | C38: =C37/C32 -> 0.785 | D38: =D37/D32 -> 0.765 | E38: =E37/E32 -> 0.745 | F38: =F37/F32 -> 0.725 | G38: =G37/G32 -> 0.705 | H38: =H37/H32 -> 0.705 | I38: ＝ EBIT ÷ 收入。可与投资者日目标「约 75%」对照
A39: 税后经营利润 NOPAT | B39: =B37*(1-$B$201) -> 170664.65 | C39: =C37*(1-$B$201) -> 185366.17 | D39: =D37*(1-$B$201) -> 205933.55 | E39: =E37*(1-$B$201) -> 224615.62 | F39: =F37*(1-$B$201) -> 240444.24 | G39: =G37*(1-$B$201) -> 252516.2 | H39: =H37*(1-$B$201) -> 261354.27 | I39: ＝ EBIT ×(1 − 有效税率)
A40: ＋ 折旧摊销 D&A | B40: =B32*$B$207 -> 15795 | C40: =C32*$B$207 -> 18164.25 | D40: =D32*$B$207 -> 20707.245 | E40: =E32*$B$207 -> 23192.114 | F40: =F32*$B$207 -> 25511.325 | G40: =G32*$B$207 -> 27552.231 | H40: =H32*$B$207 -> 28516.56 | I40: ＝ 收入 × 控制台「折旧摊销率」。★ 折旧跟随资产基数而非收入，收入下行年该比例会被动上升
A41: − 资本开支（总额） | B41: =-B32*$B$203 -> -37664.999 | C41: =-C32*$B$203 -> -43314.749 | D41: =-D32*$B$203 -> -49378.814 | E41: =-E32*$B$203 -> -55304.272 | F41: =-F32*$B$203 -> -60834.699 | G41: =-G32*$B$203 -> -65701.475 | H41: =-H32*$B$203 -> -68001.027 | I41: ＝ 收入 × 控制台「资本开支率」
A42: ＋ CHIPS 政府补贴抵扣 | B42: =-B41*$B$205 -> 3389.8499 | C42: =-C41*$B$205 -> 3898.3274 | D42: =-D41*$B$205 -> 4444.0933 | E42: =-E41*$B$205 -> 4977.3845 | F42: =-F41*$B$205 -> 5475.1229 | G42: =-G41*$B$205 -> 5913.1328 | H42: =-H41*$B$205 -> 6120.0924 | I42: ＝ 资本开支 × 控制台「政府补贴抵扣比例」
A43: 营运资本余额 | B43: =B32*$B$209 -> 32805 | C43: =C32*$B$209 -> 37725.749 | D43: =D32*$B$209 -> 43007.354 | E43: =E32*$B$209 -> 48168.237 | F43: =F32*$B$209 -> 52985.061 | G43: =G32*$B$209 -> 57223.865 | H43: =H32*$B$209 -> 59226.701 | I43: ＝ 控制台「营运资本占年化收入比」× 当年收入。期初取 FY26 Q4 年化收入 × 同一比例
...
