Workbook

Sheet 00-三表与联动
A1: SNDK · Sandisk Corporation —— 三表与联动
A2: 单位：百万美元 | 财年截止约每年 7 月初 | 数据源：公司 FY26 Q2/Q3/Q4 财报原文 | FY26 Q4 止于 2026-07-03
A4: 00 公司速览与估值锚点
A5: 项目 | B5: 数值 | D5: 口径与说明
A6: 现价（2026-08-26） | B6: 1500.17 | D6: Yahoo Finance 盘中价
A7: 市值 | B7: 219653 | D7: ＝ 现价 × 基本股数
A8: 基本股数（百万股） | B8: 146.4 | D8: 回购后；FY26末为 149M，其后继续回购
A9: 摊薄股数（百万股） | B9: 155 | D9: 公司 FY27 Q1 指引「约 155」
A10: 货币资金 | B10: 4762 | D10: FY26 Q4末资产负债表
A11: 可交易权益证券 | B11: 1777 | D11: Q4 新增；当季确认 $804M 公允价值收益
A12: 有息负债 | B12: 0 | D12: ★ FY26 Q3 起已清零，公司为净现金结构
A13: 无风险利率 Rf | B13: 0.042 | D13: 10 年期美国国债收益率
A14: 股权风险溢价 ERP | B14: 0.05 | D14: 美国成熟市场长期股权风险溢价
A15: 01 三情形估值对比（数字实时链接自后面三张 DCF 表）
A16: 情形 | B16: 每股内在价值 | C16: 相对现价 | D16: 终值占 EV | E16: FY27 收入 | F16: FY27 毛利率 | G16: FY32 毛利率 | H16: WACC | I16: 永续 g | J16: 一句话论点
A17: 悲观 | B17: ='01-DCF-悲观'!B72 -> 498.8613 | C17: ='01-DCF-悲观'!B74 -> -0.66746348 | D17: ='01-DCF-悲观'!B65 -> 0.45499456 | E17: ='01-DCF-悲观'!F13 -> 37000 | F17: ='01-DCF-悲观'!F15 -> 0.72798647 | G17: ='01-DCF-悲观'!G34 -> 0.46 | H17: ='01-DCF-悲观'!$B$209 -> 0.14 | I17: ='01-DCF-悲观'!$B$211 -> 0.025 | J17: NAND 2027 年转过剩，价格与毛利率回到历史中枢
A18: 基准 | B18: ='02-DCF-基准'!B72 -> 1630.9395 | C18: ='02-DCF-基准'!B74 -> 0.087169783 | D18: ='02-DCF-基准'!B65 -> 0.61941705 | E18: ='02-DCF-基准'!F13 -> 41849.994 | F18: ='02-DCF-基准'!F15 -> 0.80583035 | G18: ='02-DCF-基准'!G34 -> 0.68 | H18: ='02-DCF-基准'!$B$209 -> 0.12 | I18: ='02-DCF-基准'!$B$211 -> 0.03 | J18: 周期见顶但不崩塌，AI 数据中心把毛利率中枢抬到 68%–72%
A19: 乐观 | B19: ='03-DCF-乐观'!B72 -> 4068.1449 | C19: ='03-DCF-乐观'!B74 -> 1.7117893 | D19: ='03-DCF-乐观'!B65 -> 0.70816859 | E19: ='03-DCF-乐观'!F13 -> 49199.987 | F19: ='03-DCF-乐观'!F15 -> 0.84819309 | G19: ='03-DCF-乐观'!G34 -> 0.76 | H19: ='03-DCF-乐观'!$B$209 -> 0.105 | I19: ='03-DCF-乐观'!$B$211 -> 0.035 | J19: NBM 长约把存储合约化，管理层 FY28–30 框架成立
A20: 当前股价（2026-08-26） | B20: 1500.17 | C20: 52 周区间 $46.75 – $2,354.39；距峰值已回撤约 37%
A21: 卖方一致目标价 | B21: 2126 | C21: S&P Global 汇总 24 家机构，评级「买入」；最低 $1,000、最高 $3,600。区间跨度本身说明分歧极大
A22: ★ 三个情形的每股价值跨度是 $484 → $4,087，相差 8.4 倍。这不是模型不精确，而是这个行业在这个时点上真实的不确定性——卖方目标价从 $1,000 到 $3,600 的分布，说明专业机构之间的分歧同样巨大。把任何单一情形当作「答案」都是误用；正确的用法是问：什么样的证据会让我在三者之间移动。
A24: ★ 读这张表之前必须知道的三件事：① SNDK 于 2025-02-21 从西部数据（WDC）分拆独立，2025-02-21 之前为「视同独立」的划分报表，可比性有限；② 公司晶圆厂在与铠侠合资的 Flash Ventures 里，因此账面资本开支极低（FY26 仅 $177M），真实的产能投入走「向 Flash Ventures 发放票据」这条投资活动科目——做 DCF 时必须把它算作资本开支，否则会系统性高估自由现金流；③ FY26 是存储超级周期的顶点，Q4 毛利率 84.6%，把这个盈利水平外推是本模型最大的风险来源。
A26: 02 合并利润表（季度 + 年度）
A27: 科目（百万美元） | B27: FY26 Q1 | C27: FY26 Q2 | D27: FY26 Q3 | E27: FY26 Q4 | F27: FY2026 | G27: FY2025 | H27: Q4 环比 | I27: Q4 同比 | J27: FY26 同比 | K27: 备注
A28: 营业收入 Revenue, net | B28: 2308 | C28: 3025 | D28: 5950 | E28: 8965 | F28: 20248 | G28: 7355 | H28: =IF(D28=0,"n/a",E28/ABS(D28)-1) -> 0.50672269 | I28: =IF(G28=0,"n/a","n/a") -> n/a | J28: =IF(G28=0,"n/a",F28/ABS(G28)-1) -> 1.7529572
A29: 营业成本 Cost of revenue | B29: 1621 | C29: 1484 | D29: 1288 | E29: 1383 | F29: 5776 | G29: 5143 | H29: =IF(D29=0,"n/a",E29/ABS(D29)-1) -> 0.073757764 | I29: =IF(G29=0,"n/a","n/a") -> n/a | J29: =IF(G29=0,"n/a",F29/ABS(G29)-1) -> 0.12307991
A30: 毛利 Gross profit | B30: 687 | C30: 1541 | D30: 4662 | E30: 7582 | F30: 14472 | G30: 2212 | H30: =IF(D30=0,"n/a",E30/ABS(D30)-1) -> 0.62634063 | I30: =IF(G30=0,"n/a","n/a") -> n/a | J30: =IF(G30=0,"n/a",F30/ABS(G30)-1) -> 5.5424955
A31: 研发费用 R&D | B31: 316 | C31: 327 | D31: 337 | E31: 348 | F31: 1328 | G31: 1132 | H31: =IF(D31=0,"n/a",E31/ABS(D31)-1) -> 0.03264095 | I31: =IF(G31=0,"n/a","n/a") -> n/a | J31: =IF(G31=0,"n/a",F31/ABS(G31)-1) -> 0.17314488
A32: 销售管理费用 SG&A | B32: 179 | C32: 139 | D32: 161 | E32: 197 | F32: 676 | G32: 573 | H32: =IF(D32=0,"n/a",E32/ABS(D32)-1) -> 0.22360248 | I32: =IF(G32=0,"n/a","n/a") -> n/a | J32: =IF(G32=0,"n/a",F32/ABS(G32)-1) -> 0.17975567
A33: 商誉减值 Goodwill impairment | B33: 0 | C33: 0 | D33: 0 | E33: 0 | F33: 0 | G33: 1830 | H33: =IF(D33=0,"n/a",E33/ABS(D33)-1) -> n/a | I33: =IF(G33=0,"n/a","n/a") -> n/a | J33: =IF(G33=0,"n/a",F33/ABS(G33)-1) -> -1
A34: 债务清偿损失 Loss on debt exting. | B34: 0 | C34: 0 | D34: 46 | E34: 0 | F34: 46 | G34: 0 | H34: =IF(D34=0,"n/a",E34/ABS(D34)-1) -> -1 | I34: =IF(G34=0,"n/a","n/a") -> n/a | J34: =IF(G34=0,"n/a",F34/ABS(G34)-1) -> n/a
A35: 分拆费用 Business separation costs | B35: 9 | C35: 9 | D35: 7 | E35: 0 | F35: 25 | G35: 67 | H35: =IF(D35=0,"n/a",E35/ABS(D35)-1) -> -1 | I35: =IF(G35=0,"n/a","n/a") -> n/a | J35: =IF(G35=0,"n/a",F35/ABS(G35)-1) -> -0.62686567
A36: 裁员及其他 Employee term. & other | B36: -3 | C36: 1 | D36: 0 | E36: 0 | F36: -2 | G36: 21 | H36: =IF(D36=0,"n/a",E36/ABS(D36)-1) -> n/a | I36: =IF(G36=0,"n/a","n/a") -> n/a | J36: =IF(G36=0,"n/a",F36/ABS(G36)-1) -> -1.0952381
A37: 业务处置(收益)损失 Divestiture | B37: 10 | C37: 0 | D37: 0 | E37: 0 | F37: 10 | G37: -34 | H37: =IF(D37=0,"n/a",E37/ABS(D37)-1) -> n/a | I37: =IF(G37=0,"n/a","n/a") -> n/a | J37: =IF(G37=0,"n/a",F37/ABS(G37)-1) -> -0.70588235
A38: 营业费用合计 Total opex | B38: 511 | C38: 476 | D38: 551 | E38: 545 | F38: 2083 | G38: 3589 | H38: =IF(D38=0,"n/a",E38/ABS(D38)-1) -> -0.010889292 | I38: =IF(G38=0,"n/a","n/a") -> n/a | J38: =IF(G38=0,"n/a",F38/ABS(G38)-1) -> -0.41961549
A39: 营业利润 Operating income | B39: 176 | C39: 1065 | D39: 4111 | E39: 7037 | F39: 12389 | G39: -1377 | H39: =IF(D39=0,"n/a",E39/ABS(D39)-1) -> 0.71174897 | I39: =IF(G39=0,"n/a","n/a") -> n/a | J39: =IF(G39=0,"n/a",F39/ABS(G39)-1) -> 7.9970951
... A47: 净利润 Net income | B47: 112 | C47: 803 | D47: 3615 | E47: 6903 | F47: 11433 | G47: -1641 | H47: =IF(D47=0,"n/a",E47/ABS(D47)-1) -> 0.90954357 | I47: =IF(G47=0,"n/a","n/a") -> n/a | J47: =IF(G47=0,"n/a",F47/ABS(G47)-1) -> 5.9670932
A48: 毛利率 Gross margin | B48: =B30/B28 -> 0.29766031 | C48: =C30/C28 -> 0.50942149 | D48: =D30/D28 -> 0.78352941 | E48: =E30/E28 -> 0.84573341 | F48: =F30/F28 -> 0.71473726 | G48: =G30/G28 -> 0.30074779
A49: 营业利润率 Operating margin | B49: =B39/B28 -> 0.076256499 | C49: =C39/C28 -> 0.35206612 | D49: =D39/D28 -> 0.69092437 | E49: =E39/E28 -> 0.78494144 | F49: =F39/F28 -> 0.6118629 | G49: =G39/G28 -> -0.18721958
A50: 净利率 Net margin | B50: =B47/B28 -> 0.048526863 | C50: =C47/C28 -> 0.26545455 | D50: =D47/D28 -> 0.60756303 | E50: =E47/E28 -> 0.76999442 | F50: =F47/F28 -> 0.56464836 | G50: =G47/G28 -> -0.22311353
...

Sheet 01-DCF-悲观
A1: BEAR · SNDK 现金流折现模型 —— 悲观情形
A2: FY2027 分四个季度 → FY2028–FY2032 按年 → 永续 | 自由现金流口径：FCFF（含 Flash Ventures 投入） | ▼ 全部参数由本表底部的参数控制台滑标驱动
A4: 00 本情形的论点：这套数字建立在什么判断之上
A5: 承接《缺口的算术》NAND 侧的结论：层数堆叠与 QLC 让 NAND 供给可以在不建厂的情况下快速放大，2027 年 NAND 先于 DRAM 转向过剩。本情形假设合约价在 FY27 下半年见顶回落，FY28 出现典型的存储下行周期——价格跌幅快于成本，毛利率从 84.6% 一路回到 40% 出头的历史中枢。
A6: 1．FY27 下半年合约价环比转负，Q4 收入回到 $7.1B（≈ FY26 Q4 水平的 79%）
A7: 2．FY28 收入 −34%、毛利率回到 42%——接近 SNDK 分拆前的正常年份
A8: 3．NBM 长约只锁量不锁价，价格下行时无法保护利润率
A9: 4．WACC 用 14%（周期底部风险溢价上升），永续增长 2.5%
A11: 01 FY2027 季度预测（SNDK 分拆才一年半，先用季度把最近的可见度做实）
A12: 科目（百万美元） | B12: FY27 Q1 | C12: FY27 Q2 | D12: FY27 Q3 | E12: FY27 Q4 | F12: FY2027 合计 | G12: 变量怎么来的
A13: 营业收入 | B13: =$B$189 -> 10550 | C13: =B13*(1+-0.009479+$B$191) -> 10449.997 | D13: =C13*(1+-0.148325+$B$191) -> 8900.0008 | E13: =D13*(1+-0.202247+$B$191) -> 7100.0023 | F13: =SUM(B13:E13) -> 37000 | G13: Q1 ＝ 控制台滑标（官方指引 $10.3–10.8B）；Q2–Q4 ＝ 上一季 ×(1 + 情形环比增速 + 滑标平移)
A14: 环比增速 QoQ | B14: =B13/'00-三表与联动'!E28-1 -> 0.17679866 | C14: =C13/B13-1 -> -0.009479 | D14: =D13/C13-1 -> -0.148325 | E14: =E13/D13-1 -> -0.202247 | F14: =F13/'00-三表与联动'!F28-1 -> 0.82734096 | G14: Q1 的环比基数是 FY26 Q4 的 $8,965M（不是 FY26 全年）；Q2–Q4 为上一季
A15: 毛利率 | B15: =MAX(0.05,MIN(0.92,0.83+$B$193)) -> 0.83 | C15: =MAX(0.05,MIN(0.92,0.78+$B$193)) -> 0.78 | D15: =MAX(0.05,MIN(0.92,0.68+$B$193)) -> 0.68 | E15: =MAX(0.05,MIN(0.92,0.56+$B$193)) -> 0.56 | F15: =F16/F13 -> 0.72798647 | G15: 情形设定的季度毛利率路径 + 控制台「毛利率平移」，上下限锁在 5%–92%
A16: 毛利 | B16: =B13*B15 -> 8756.5 | C16: =C13*C15 -> 8150.9973 | D16: =D13*D15 -> 6052.0006 | E16: =E13*E15 -> 3976.0013 | F16: =SUM(B16:E16) -> 26935.499 | G16: ＝ 收入 × 毛利率
A17: 营业费用 | B17: =B13*$B$199 -> 738.5 | C17: =C13*$B$199 -> 731.49976 | D17: =D13*$B$199 -> 623.00006 | E17: =E13*$B$199 -> 497.00016 | F17: =SUM(B17:E17) -> 2590 | G17: ＝ 收入 × 控制台「营业费用率」。公司 FY27 Q1 GAAP 指引为 $574–614M
A18: 营业利润 EBIT | B18: =B16-B17 -> 8018 | C18: =C16-C17 -> 7419.4976 | D18: =D16-D17 -> 5429.0005 | E18: =E16-E17 -> 3479.0012 | F18: =SUM(B18:E18) -> 24345.499 | G18: ＝ 毛利 − 营业费用
A19: 营业利润率 | B19: =B18/B13 -> 0.76 | C19: =C18/C13 -> 0.71 | D19: =D18/D13 -> 0.61 | E19: =E18/E13 -> 0.49 | F19: =F18/F13 -> 0.65798647 | G19: ＝ EBIT ÷ 收入
A20: 所得税 | B20: =MAX(0,B18)*$B$201 -> 1363.06 | C20: =MAX(0,C18)*$B$201 -> 1261.3146 | D20: =MAX(0,D18)*$B$201 -> 922.93008 | E20: =MAX(0,E18)*$B$201 -> 591.4302 | F20: =SUM(B20:E20) -> 4138.7349 | G20: ＝ EBIT × 控制台「有效税率」（FCFF 口径按 EBIT 计税，不含利息）
A21: 税后经营利润 NOPAT | B21: =B18-B20 -> 6654.94 | C21: =C18-C20 -> 6158.183 | D21: =D18-D20 -> 4506.0704 | E21: =E18-E20 -> 2887.571 | F21: =SUM(B21:E21) -> 20206.764 | G21: ＝ EBIT − 所得税
A22: ＋ 折旧摊销 D&A | B22: =B13*0.0074 -> 78.07 | C22: =C13*0.0074 -> 77.329974 | D22: =D13*0.0074 -> 65.860006 | E22: =E13*0.0074 -> 52.540017 | F22: =SUM(B22:E22) -> 273.8 | G22: ＝ 收入 × 0.74%（FY26 实际 D&A $149M ÷ 收入 $20,248M）。数字极低是因为晶圆厂在合资公司里，折旧不落在 SNDK 报表上
A23: − 自有资本开支 | B23: =-B13*$B$203 -> -189.9 | C23: =-C13*$B$203 -> -188.09994 | D23: =-D13*$B$203 -> -160.20001 | E23: =-E13*$B$203 -> -127.80004 | F23: =SUM(B23:E23) -> -665.99999 | G23: ＝ 收入 × 控制台「自有资本开支率」。FY26 实际 0.87%
A24: − Flash Ventures 净投入 | B24: =-B13*$B$205 -> -390.35 | C24: =-C13*$B$205 -> -386.64987 | D24: =-D13*$B$205 -> -329.30003 | E24: =-E13*$B$205 -> -262.70009 | F24: =SUM(B24:E24) -> -1369 | G24: ＝ 收入 × 控制台「FV 净投入率」。FY26 实际 1.36%（发放票据 462 − 回收 187）
A25: 营运资本余额 | B25: =B13*4*$B$207 -> 8440 | C25: =C13*4*$B$207 -> 8359.9972 | D25: =D13*4*$B$207 -> 7120.0006 | E25: =E13*4*$B$207 -> 5680.0019 | F25: =E25 -> 5680.0019 | G25: ＝ 控制台「营运资本占年化收入比」× 当季收入 × 4。期初取 FY26 Q4 的年化收入基准
A26: − 营运资本增加 ΔNWC | B26: =-(B25-'00-三表与联动'!E28*4*$B$207) -> -1268 | C26: =-(C25-B25) -> 80.00276 | D26: =-(D25-C25) -> 1239.9966 | E26: =-(E25-D25) -> 1439.9988 | F26: =SUM(B26:E26) -> 1491.9981 | G26: ＝ 本季余额 − 上季余额。余额法，不再用「占收入增量比」
A27: ＝ 自由现金流 FCFF | B27: =B21+B22+B23+B24+B26 -> 4884.76 | C27: =C21+C22+C23+C24+C26 -> 5740.7659 | D27: =D21+D22+D23+D24+D26 -> 5322.427 | E27: =E21+E22+E23+E24+E26 -> 3989.6096 | F27: =SUM(B27:E27) -> 19937.562 | G27: ＝ NOPAT + D&A − 自有资本开支 − FV 净投入 − ΔNWC
A28: 口径说明：这里算的是 FCFF（企业自由现金流），所以税按 EBIT 计、不扣利息——利息的价值已经体现在折现率里。公司目前零负债，FCFF 与 FCFE 的差异只剩利息收入。
A30: 02 FY2028–FY2032 年度预测 + 永续
A31: 科目（百万美元） | B31: FY2027 | C31: FY2028 | D31: FY2029 | E31: FY2030 | F31: FY2031 | G31: FY2032 | H31: 永续期 | I31: 变量怎么来的
A32: 营业收入 | B32: =F13 -> 37000 | C32: =B32*(1+-0.34) -> 24420 | D32: =C32*(1+-0.1+$B$197) -> 21978 | E32: =D32*(1+0.12+$B$197) -> 24615.36 | F32: =E32*(1+0.1+$B$197) -> 27076.896 | G32: =F32*(1+0.08+$B$197) -> 29243.047 | H32: =G32*(1+$B$211) -> 29974.124 | I32: FY27 取季度合计；FY28 ＝ 情形设定增速；FY29–32 ＝ 情形增速 + 控制台「长期增速平移」
A33: 收入增速 YoY | B33: =B32/'00-三表与联动'!F28-1 -> 0.82734096 | C33: =C32/B32-1 -> -0.34 | D33: =D32/C32-1 -> -0.1 | E33: =E32/D32-1 -> 0.12 | F33: =F32/E32-1 -> 0.1 | G33: =G32/F32-1 -> 0.08 | H33: =$B$211 -> 0.025 | I33: 逐年同比。FY26 实际为 +175%
A34: 毛利率 | B34: =F16/F13 -> 0.72798647 | C34: =MAX(0.05,MIN(0.92,0.42+$B$193)) -> 0.42 | D34: =MAX(0.05,MIN(0.92,0.36+$B$193)) -> 0.36 | E34: =MAX(0.05,MIN(0.92,0.43+$B$193)) -> 0.43 | F34: =MAX(0.05,MIN(0.92,0.46+$B$193)) -> 0.46 | G34: =$B$195 -> 0.46 | H34: =G34 -> 0.46 | I34: 情形设定的年度毛利率 + 控制台「毛利率平移」；FY32 直接取控制台「终局毛利率」
A35: 毛利 | B35: =B32*B34 -> 26935.499 | C35: =C32*C34 -> 10256.4 | D35: =D32*D34 -> 7912.0799 | E35: =E32*E34 -> 10584.605 | F35: =F32*F34 -> 12455.372 | G35: =G32*G34 -> 13451.802 | H35: =H32*H34 -> 13788.097 | I35: ＝ 收入 × 毛利率
A36: 营业费用 | B36: =B32*$B$199 -> 2590 | C36: =C32*$B$199 -> 1709.4 | D36: =D32*$B$199 -> 1538.46 | E36: =E32*$B$199 -> 1723.0752 | F36: =F32*$B$199 -> 1895.3827 | G36: =G32*$B$199 -> 2047.0133 | H36: =H32*$B$199 -> 2098.1887 | I36: ＝ 收入 × 控制台「营业费用率」
A37: 营业利润 EBIT | B37: =B35-B36 -> 24345.499 | C37: =C35-C36 -> 8546.9999 | D37: =D35-D36 -> 6373.6199 | E37: =E35-E36 -> 8861.5295 | F37: =F35-F36 -> 10559.989 | G37: =G35-G36 -> 11404.789 | H37: =H35-H36 -> 11689.908 | I37: ＝ 毛利 − 营业费用
A38: 营业利润率 | B38: =B37/B32 -> 0.65798647 | C38: =C37/C32 -> 0.35 | D38: =D37/D32 -> 0.29 | E38: =E37/E32 -> 0.36 | F38: =F37/F32 -> 0.39 | G38: =G37/G32 -> 0.39 | H38: =H37/H32 -> 0.39 | I38: ＝ EBIT ÷ 收入。可与投资者日目标「约 75%」对照
A39: 税后经营利润 NOPAT | B39: =B37*(1-$B$201) -> 20206.764 | C39: =C37*(1-$B$201) -> 7094.0099 | D39: =D37*(1-$B$201) -> 5290.1046 | E39: =E37*(1-$B$201) -> 7355.0695 | F39: =F37*(1-$B$201) -> 8764.7912 | G39: =G37*(1-$B$201) -> 9465.9745 | H39: =H37*(1-$B$201) -> 9702.6238 | I39: ＝ EBIT ×(1 − 有效税率)
A40: ＋ 折旧摊销 D&A | B40: =B32*0.0074 -> 273.8 | C40: =C32*0.0074 -> 180.708 | D40: =D32*0.0074 -> 162.6372 | E40: =E32*0.0074 -> 182.15366 | F40: =F32*0.0074 -> 200.36903 | G40: =G32*0.0074 -> 216.39855 | H40: =H32*0.0074 -> 221.80851 | I40: ＝ 收入 × 0.74%
A41: − 自有资本开支 | B41: =-B32*$B$203 -> -665.99999 | C41: =-C32*$B$203 -> -439.56 | D41: =-D32*$B$203 -> -395.604 | E41: =-E32*$B$203 -> -443.07648 | F41: =-F32*$B$203 -> -487.38412 | G41: =-G32*$B$203 -> -526.37485 | H41: =-H32*$B$203 -> -539.53423 | I41: ＝ 收入 × 控制台「自有资本开支率」
A42: − Flash Ventures 净投入 | B42: =-B32*$B$205 -> -1369 | C42: =-C32*$B$205 -> -903.53999 | D42: =-D32*$B$205 -> -813.18599 | E42: =-E32*$B$205 -> -910.76831 | F42: =-F32*$B$205 -> -1001.8451 | G42: =-G32*$B$205 -> -1081.9928 | H42: =-H32*$B$205 -> -1109.0426 | I42: ＝ 收入 × 控制台「FV 净投入率」
A43: 营运资本余额 | B43: =B32*$B$207 -> 7399.9999 | C43: =C32*$B$207 -> 4884 | D43: =D32*$B$207 -> 4395.6 | E43: =E32*$B$207 -> 4923.072 | F43: =F32*$B$207 -> 5415.3792 | G43: =G32*$B$207 -> 5848.6095 | H43: =H32*$B$207 -> 5994.8247 | I43: ＝ 控制台「营运资本占年化收入比」× 当年收入。期初取 FY26 Q4 年化收入 × 同一比例
...

Sheet 02-DCF-基准
A1: BASE · SNDK 现金流折现模型 —— 基准情形
A2: FY2027 分四个季度 → FY2028–FY2032 按年 → 永续 | 自由现金流口径：FCFF（含 Flash Ventures 投入） | ▼ 全部参数由本表底部的参数控制台滑标驱动
A4: 00 本情形的论点：这套数字建立在什么判断之上
A5: 采用公司 FY27 Q1 指引中值作为起点，但不接受管理层「FY28–30 毛利率维持 80%」的长期框架。本情形假设周期在 FY27 见顶、FY28 温和回落一年，之后由 AI 数据中心需求托住，毛利率稳定在 66%–72% 这个「比历史高、但低于当前峰值」的新中枢。
A6: 1．FY27 Q1 用官方指引中值 $10.55B（区间 $10.30–10.80B）
A7: 2．FY28 收入 −18%：一次温和的库存与价格修正，而非崩塌
A8: 3．FY29–FY32 收入回到中双位数增长，与管理层的 bit 增长口径一致
A9: 4．终局毛利率 68%，显著高于分拆前的 30%，但低于管理层的 80%
A11: 01 FY2027 季度预测（SNDK 分拆才一年半，先用季度把最近的可见度做实）
A12: 科目（百万美元） | B12: FY27 Q1 | C12: FY27 Q2 | D12: FY27 Q3 | E12: FY27 Q4 | F12: FY2027 合计 | G12: 变量怎么来的
A13: 营业收入 | B13: =$B$189 -> 10550 | C13: =B13*(1+0.061611+$B$191) -> 11199.996 | D13: =C13*(1+-0.053571+$B$191) -> 10600.001 | E13: =D13*(1+-0.103774+$B$191) -> 9499.9966 | F13: =SUM(B13:E13) -> 41849.994 | G13: Q1 ＝ 控制台滑标（官方指引 $10.3–10.8B）；Q2–Q4 ＝ 上一季 ×(1 + 情形环比增速 + 滑标平移)
A14: 环比增速 QoQ | B14: =B13/'00-三表与联动'!E28-1 -> 0.17679866 | C14: =C13/B13-1 -> 0.061611 | D14: =D13/C13-1 -> -0.053571 | E14: =E13/D13-1 -> -0.103774 | F14: =F13/'00-三表与联动'!F28-1 -> 1.0668705 | G14: Q1 的环比基数是 FY26 Q4 的 $8,965M（不是 FY26 全年）；Q2–Q4 为上一季
A15: 毛利率 | B15: =MAX(0.05,MIN(0.92,0.84+$B$193)) -> 0.84 | C15: =MAX(0.05,MIN(0.92,0.835+$B$193)) -> 0.835 | D15: =MAX(0.05,MIN(0.92,0.8+$B$193)) -> 0.8 | E15: =MAX(0.05,MIN(0.92,0.74+$B$193)) -> 0.74 | F15: =F16/F13 -> 0.80583035 | G15: 情形设定的季度毛利率路径 + 控制台「毛利率平移」，上下限锁在 5%–92%
A16: 毛利 | B16: =B13*B15 -> 8862 | C16: =C13*C15 -> 9351.9967 | D16: =D13*D15 -> 8480.0008 | E16: =E13*E15 -> 7029.9974 | F16: =SUM(B16:E16) -> 33723.995 | G16: ＝ 收入 × 毛利率
A17: 营业费用 | B17: =B13*$B$199 -> 611.9 | C17: =C13*$B$199 -> 649.59977 | D17: =D13*$B$199 -> 614.80006 | E17: =E13*$B$199 -> 550.9998 | F17: =SUM(B17:E17) -> 2427.2996 | G17: ＝ 收入 × 控制台「营业费用率」。公司 FY27 Q1 GAAP 指引为 $574–614M
A18: 营业利润 EBIT | B18: =B16-B17 -> 8250.1 | C18: =C16-C17 -> 8702.3969 | D18: =D16-D17 -> 7865.2008 | E18: =E16-E17 -> 6478.9976 | F18: =SUM(B18:E18) -> 31296.695 | G18: ＝ 毛利 − 营业费用
A19: 营业利润率 | B19: =B18/B13 -> 0.782 | C19: =C18/C13 -> 0.777 | D19: =D18/D13 -> 0.742 | E19: =E18/E13 -> 0.682 | F19: =F18/F13 -> 0.74783035 | G19: ＝ EBIT ÷ 收入
A20: 所得税 | B20: =MAX(0,B18)*$B$201 -> 1320.016 | C20: =MAX(0,C18)*$B$201 -> 1392.3835 | D20: =MAX(0,D18)*$B$201 -> 1258.4321 | E20: =MAX(0,E18)*$B$201 -> 1036.6396 | F20: =SUM(B20:E20) -> 5007.4713 | G20: ＝ EBIT × 控制台「有效税率」（FCFF 口径按 EBIT 计税，不含利息）
A21: 税后经营利润 NOPAT | B21: =B18-B20 -> 6930.084 | C21: =C18-C20 -> 7310.0134 | D21: =D18-D20 -> 6606.7687 | E21: =E18-E20 -> 5442.358 | F21: =SUM(B21:E21) -> 26289.224 | G21: ＝ EBIT − 所得税
A22: ＋ 折旧摊销 D&A | B22: =B13*0.0074 -> 78.07 | C22: =C13*0.0074 -> 82.879971 | D22: =D13*0.0074 -> 78.440008 | E22: =E13*0.0074 -> 70.299974 | F22: =SUM(B22:E22) -> 309.68995 | G22: ＝ 收入 × 0.74%（FY26 实际 D&A $149M ÷ 收入 $20,248M）。数字极低是因为晶圆厂在合资公司里，折旧不落在 SNDK 报表上
A23: − 自有资本开支 | B23: =-B13*$B$203 -> -189.9 | C23: =-C13*$B$203 -> -201.59993 | D23: =-D13*$B$203 -> -190.80002 | E23: =-E13*$B$203 -> -170.99994 | F23: =SUM(B23:E23) -> -753.29989 | G23: ＝ 收入 × 控制台「自有资本开支率」。FY26 实际 0.87%
A24: − Flash Ventures 净投入 | B24: =-B13*$B$205 -> -337.6 | C24: =-C13*$B$205 -> -358.39987 | D24: =-D13*$B$205 -> -339.20003 | E24: =-E13*$B$205 -> -303.99989 | F24: =SUM(B24:E24) -> -1339.1998 | G24: ＝ 收入 × 控制台「FV 净投入率」。FY26 实际 1.36%（发放票据 462 − 回收 187）
A25: 营运资本余额 | B25: =B13*4*$B$207 -> 7596 | C25: =C13*4*$B$207 -> 8063.9972 | D25: =D13*4*$B$207 -> 7632.0008 | E25: =E13*4*$B$207 -> 6839.9975 | F25: =E25 -> 6839.9975 | G25: ＝ 控制台「营运资本占年化收入比」× 当季收入 × 4。期初取 FY26 Q4 的年化收入基准
A26: − 营运资本增加 ΔNWC | B26: =-(B25-'00-三表与联动'!E28*4*$B$207) -> -1141.2 | C26: =-(C25-B25) -> -467.99716 | D26: =-(D25-C25) -> 431.99639 | E26: =-(E25-D25) -> 792.00325 | F26: =SUM(B26:E26) -> -385.19752 | G26: ＝ 本季余额 − 上季余额。余额法，不再用「占收入增量比」
A27: ＝ 自由现金流 FCFF | B27: =B21+B22+B23+B24+B26 -> 5339.454 | C27: =C21+C22+C23+C24+C26 -> 6364.8964 | D27: =D21+D22+D23+D24+D26 -> 6587.205 | E27: =E21+E22+E23+E24+E26 -> 5829.6614 | F27: =SUM(B27:E27) -> 24121.217 | G27: ＝ NOPAT + D&A − 自有资本开支 − FV 净投入 − ΔNWC
A28: 口径说明：这里算的是 FCFF（企业自由现金流），所以税按 EBIT 计、不扣利息——利息的价值已经体现在折现率里。公司目前零负债，FCFF 与 FCFE 的差异只剩利息收入。
A30: 02 FY2028–FY2032 年度预测 + 永续
A31: 科目（百万美元） | B31: FY2027 | C31: FY2028 | D31: FY2029 | E31: FY2030 | F31: FY2031 | G31: FY2032 | H31: 永续期 | I31: 变量怎么来的
A32: 营业收入 | B32: =F13 -> 41849.994 | C32: =B32*(1+-0.18) -> 34316.995 | D32: =C32*(1+0.14+$B$197) -> 39121.374 | E32: =D32*(1+0.15+$B$197) -> 44989.58 | F32: =E32*(1+0.12+$B$197) -> 50388.33 | G32: =F32*(1+0.1+$B$197) -> 55427.163 | H32: =G32*(1+$B$211) -> 57089.978 | I32: FY27 取季度合计；FY28 ＝ 情形设定增速；FY29–32 ＝ 情形增速 + 控制台「长期增速平移」
A33: 收入增速 YoY | B33: =B32/'00-三表与联动'!F28-1 -> 1.0668705 | C33: =C32/B32-1 -> -0.18 | D33: =D32/C32-1 -> 0.14 | E33: =E32/D32-1 -> 0.15 | F33: =F32/E32-1 -> 0.12 | G33: =G32/F32-1 -> 0.1 | H33: =$B$211 -> 0.03 | I33: 逐年同比。FY26 实际为 +175%
A34: 毛利率 | B34: =F16/F13 -> 0.80583035 | C34: =MAX(0.05,MIN(0.92,0.66+$B$193)) -> 0.66 | D34: =MAX(0.05,MIN(0.92,0.7+$B$193)) -> 0.7 | E34: =MAX(0.05,MIN(0.92,0.72+$B$193)) -> 0.72 | F34: =MAX(0.05,MIN(0.92,0.7+$B$193)) -> 0.7 | G34: =$B$195 -> 0.68 | H34: =G34 -> 0.68 | I34: 情形设定的年度毛利率 + 控制台「毛利率平移」；FY32 直接取控制台「终局毛利率」
A35: 毛利 | B35: =B32*B34 -> 33723.995 | C35: =C32*C34 -> 22649.217 | D35: =D32*D34 -> 27384.962 | E35: =E32*E34 -> 32392.498 | F35: =F32*F34 -> 35271.831 | G35: =G32*G34 -> 37690.471 | H35: =H32*H34 -> 38821.185 | I35: ＝ 收入 × 毛利率
A36: 营业费用 | B36: =B32*$B$199 -> 2427.2996 | C36: =C32*$B$199 -> 1990.3857 | D36: =D32*$B$199 -> 2269.0397 | E36: =E32*$B$199 -> 2609.3957 | F36: =F32*$B$199 -> 2922.5231 | G36: =G32*$B$199 -> 3214.7754 | H36: =H32*$B$199 -> 3311.2187 | I36: ＝ 收入 × 控制台「营业费用率」
A37: 营业利润 EBIT | B37: =B35-B36 -> 31296.695 | C37: =C35-C36 -> 20658.831 | D37: =D35-D36 -> 25115.922 | E37: =E35-E36 -> 29783.102 | F37: =F35-F36 -> 32349.308 | G37: =G35-G36 -> 34475.695 | H37: =H35-H36 -> 35509.966 | I37: ＝ 毛利 − 营业费用
A38: 营业利润率 | B38: =B37/B32 -> 0.74783035 | C38: =C37/C32 -> 0.602 | D38: =D37/D32 -> 0.642 | E38: =E37/E32 -> 0.662 | F38: =F37/F32 -> 0.642 | G38: =G37/G32 -> 0.622 | H38: =H37/H32 -> 0.622 | I38: ＝ EBIT ÷ 收入。可与投资者日目标「约 75%」对照
A39: 税后经营利润 NOPAT | B39: =B37*(1-$B$201) -> 26289.224 | C39: =C37*(1-$B$201) -> 17353.418 | D39: =D37*(1-$B$201) -> 21097.375 | E39: =E37*(1-$B$201) -> 25017.806 | F39: =F37*(1-$B$201) -> 27173.419 | G39: =G37*(1-$B$201) -> 28959.584 | H39: =H37*(1-$B$201) -> 29828.372 | I39: ＝ EBIT ×(1 − 有效税率)
A40: ＋ 折旧摊销 D&A | B40: =B32*0.0074 -> 309.68995 | C40: =C32*0.0074 -> 253.94576 | D40: =D32*0.0074 -> 289.49817 | E40: =E32*0.0074 -> 332.92289 | F40: =F32*0.0074 -> 372.87364 | G40: =G32*0.0074 -> 410.161 | H40: =H32*0.0074 -> 422.46583 | I40: ＝ 收入 × 0.74%
A41: − 自有资本开支 | B41: =-B32*$B$203 -> -753.29989 | C41: =-C32*$B$203 -> -617.70591 | D41: =-D32*$B$203 -> -704.18473 | E41: =-E32*$B$203 -> -809.81244 | F41: =-F32*$B$203 -> -906.98994 | G41: =-G32*$B$203 -> -997.68893 | H41: =-H32*$B$203 -> -1027.6196 | I41: ＝ 收入 × 控制台「自有资本开支率」
A42: − Flash Ventures 净投入 | B42: =-B32*$B$205 -> -1339.1998 | C42: =-C32*$B$205 -> -1098.1438 | D42: =-D32*$B$205 -> -1251.884 | E42: =-E32*$B$205 -> -1439.6666 | F42: =-F32*$B$205 -> -1612.4266 | G42: =-G32*$B$205 -> -1773.6692 | H42: =-H32*$B$205 -> -1826.8793 | I42: ＝ 收入 × 控制台「FV 净投入率」
A43: 营运资本余额 | B43: =B32*$B$207 -> 7532.9989 | C43: =C32*$B$207 -> 6177.0591 | D43: =D32*$B$207 -> 7041.8473 | E43: =E32*$B$207 -> 8098.1244 | F43: =F32*$B$207 -> 9069.8994 | G43: =G32*$B$207 -> 9976.8893 | H43: =H32*$B$207 -> 10276.196 | I43: ＝ 控制台「营运资本占年化收入比」× 当年收入。期初取 FY26 Q4 年化收入 × 同一比例
...

Sheet 03-DCF-乐观
A1: BULL · SNDK 现金流折现模型 —— 乐观情形
A2: FY2027 分四个季度 → FY2028–FY2032 按年 → 永续 | 自由现金流口径：FCFF（含 Flash Ventures 投入） | ▼ 全部参数由本表底部的参数控制台滑标驱动
A4: 00 本情形的论点：这套数字建立在什么判断之上
A5: 直接采用公司 2026 投资者日给出的 FY2028–FY2030 长期框架：收入中高双位数增长、非 GAAP 毛利率约 80%、营业利润率约 75%、费用率约 5%、调整后自由现金流率约 50%。背后的逻辑是 NBM 长约锁定了 FY28 三分之二的 bit，把存储从周期股变成了合约制生意。
A6: 1．FY27 Q1 取指引上沿附近 $10.70B，其后随数据中心放量继续爬坡
A7: 2．FY28–FY30 完全对齐投资者日框架：收入 +16%~18%、毛利率 80%
A8: 3．NBM 长约把周期性削平——这是本情形与另外两个情形最根本的分歧点
A9: 4．WACC 降到 10.5%（现金流可预测性提高），永续增长 3.5%
A11: 01 FY2027 季度预测（SNDK 分拆才一年半，先用季度把最近的可见度做实）
A12: 科目（百万美元） | B12: FY27 Q1 | C12: FY27 Q2 | D12: FY27 Q3 | E12: FY27 Q4 | F12: FY2027 合计 | G12: 变量怎么来的
A13: 营业收入 | B13: =$B$189 -> 10700 | C13: =B13*(1+0.121495+$B$191) -> 11999.996 | D13: =C13*(1+0.083333+$B$191) -> 12999.992 | E13: =D13*(1+0.038462+$B$191) -> 13499.998 | F13: =SUM(B13:E13) -> 49199.987 | G13: Q1 ＝ 控制台滑标（官方指引 $10.3–10.8B）；Q2–Q4 ＝ 上一季 ×(1 + 情形环比增速 + 滑标平移)
A14: 环比增速 QoQ | B14: =B13/'00-三表与联动'!E28-1 -> 0.1935304 | C14: =C13/B13-1 -> 0.121495 | D14: =D13/C13-1 -> 0.083333 | E14: =E13/D13-1 -> 0.038462 | F14: =F13/'00-三表与联动'!F28-1 -> 1.429869 | G14: Q1 的环比基数是 FY26 Q4 的 $8,965M（不是 FY26 全年）；Q2–Q4 为上一季
A15: 毛利率 | B15: =MAX(0.05,MIN(0.92,0.848+$B$193)) -> 0.848 | C15: =MAX(0.05,MIN(0.92,0.85+$B$193)) -> 0.85 | D15: =MAX(0.05,MIN(0.92,0.85+$B$193)) -> 0.85 | E15: =MAX(0.05,MIN(0.92,0.845+$B$193)) -> 0.845 | F15: =F16/F13 -> 0.84819309 | G15: 情形设定的季度毛利率路径 + 控制台「毛利率平移」，上下限锁在 5%–92%
A16: 毛利 | B16: =B13*B15 -> 9073.6 | C16: =C13*C15 -> 10199.997 | D16: =D13*D15 -> 11049.993 | E16: =E13*E15 -> 11407.498 | F16: =SUM(B16:E16) -> 41731.089 | G16: ＝ 收入 × 毛利率
A17: 营业费用 | B17: =B13*$B$199 -> 535 | C17: =C13*$B$199 -> 599.99982 | D17: =D13*$B$199 -> 649.99961 | E17: =E13*$B$199 -> 674.9999 | F17: =SUM(B17:E17) -> 2459.9993 | G17: ＝ 收入 × 控制台「营业费用率」。公司 FY27 Q1 GAAP 指引为 $574–614M
A18: 营业利润 EBIT | B18: =B16-B17 -> 8538.6 | C18: =C16-C17 -> 9599.9972 | D18: =D16-D17 -> 10399.994 | E18: =E16-E17 -> 10732.498 | F18: =SUM(B18:E18) -> 39271.089 | G18: ＝ 毛利 − 营业费用
A19: 营业利润率 | B19: =B18/B13 -> 0.798 | C19: =C18/C13 -> 0.8 | D19: =D18/D13 -> 0.8 | E19: =E18/E13 -> 0.795 | F19: =F18/F13 -> 0.79819309 | G19: ＝ EBIT ÷ 收入
A20: 所得税 | B20: =MAX(0,B18)*$B$201 -> 1280.79 | C20: =MAX(0,C18)*$B$201 -> 1439.9996 | D20: =MAX(0,D18)*$B$201 -> 1559.9991 | E20: =MAX(0,E18)*$B$201 -> 1609.8748 | F20: =SUM(B20:E20) -> 5890.6634 | G20: ＝ EBIT × 控制台「有效税率」（FCFF 口径按 EBIT 计税，不含利息）
A21: 税后经营利润 NOPAT | B21: =B18-B20 -> 7257.81 | C21: =C18-C20 -> 8159.9976 | D21: =D18-D20 -> 8839.9947 | E21: =E18-E20 -> 9122.6236 | F21: =SUM(B21:E21) -> 33380.426 | G21: ＝ EBIT − 所得税
A22: ＋ 折旧摊销 D&A | B22: =B13*0.0074 -> 79.18 | C22: =C13*0.0074 -> 88.799974 | D22: =D13*0.0074 -> 96.199942 | E22: =E13*0.0074 -> 99.899985 | F22: =SUM(B22:E22) -> 364.0799 | G22: ＝ 收入 × 0.74%（FY26 实际 D&A $149M ÷ 收入 $20,248M）。数字极低是因为晶圆厂在合资公司里，折旧不落在 SNDK 报表上
A23: − 自有资本开支 | B23: =-B13*$B$203 -> -181.9 | C23: =-C13*$B$203 -> -203.99994 | D23: =-D13*$B$203 -> -220.99987 | E23: =-E13*$B$203 -> -229.49996 | F23: =SUM(B23:E23) -> -836.39977 | G23: ＝ 收入 × 控制台「自有资本开支率」。FY26 实际 0.87%
A24: − Flash Ventures 净投入 | B24: =-B13*$B$205 -> -299.6 | C24: =-C13*$B$205 -> -335.9999 | D24: =-D13*$B$205 -> -363.99978 | E24: =-E13*$B$205 -> -377.99994 | F24: =SUM(B24:E24) -> -1377.5996 | G24: ＝ 收入 × 控制台「FV 净投入率」。FY26 实际 1.36%（发放票据 462 − 回收 187）
A25: 营运资本余额 | B25: =B13*4*$B$207 -> 6848 | C25: =C13*4*$B$207 -> 7679.9978 | D25: =D13*4*$B$207 -> 8319.995 | E25: =E13*4*$B$207 -> 8639.9987 | F25: =E25 -> 8639.9987 | G25: ＝ 控制台「营运资本占年化收入比」× 当季收入 × 4。期初取 FY26 Q4 的年化收入基准
A26: − 营运资本增加 ΔNWC | B26: =-(B25-'00-三表与联动'!E28*4*$B$207) -> -1110.4 | C26: =-(C25-B25) -> -831.99776 | D26: =-(D25-C25) -> -639.99725 | E26: =-(E25-D25) -> -320.00365 | F26: =SUM(B26:E26) -> -2902.3987 | G26: ＝ 本季余额 − 上季余额。余额法，不再用「占收入增量比」
A27: ＝ 自由现金流 FCFF | B27: =B21+B22+B23+B24+B26 -> 5745.09 | C27: =C21+C22+C23+C24+C26 -> 6876.8 | D27: =D21+D22+D23+D24+D26 -> 7711.1977 | E27: =E21+E22+E23+E24+E26 -> 8295.02 | F27: =SUM(B27:E27) -> 28628.108 | G27: ＝ NOPAT + D&A − 自有资本开支 − FV 净投入 − ΔNWC
A28: 口径说明：这里算的是 FCFF（企业自由现金流），所以税按 EBIT 计、不扣利息——利息的价值已经体现在折现率里。公司目前零负债，FCFF 与 FCFE 的差异只剩利息收入。
A30: 02 FY2028–FY2032 年度预测 + 永续
A31: 科目（百万美元） | B31: FY2027 | C31: FY2028 | D31: FY2029 | E31: FY2030 | F31: FY2031 | G31: FY2032 | H31: 永续期 | I31: 变量怎么来的
A32: 营业收入 | B32: =F13 -> 49199.987 | C32: =B32*(1+0.18) -> 58055.984 | D32: =C32*(1+0.17+$B$197) -> 67925.502 | E32: =D32*(1+0.16+$B$197) -> 78793.582 | F32: =E32*(1+0.12+$B$197) -> 88248.812 | G32: =F32*(1+0.1+$B$197) -> 97073.693 | H32: =G32*(1+$B$211) -> 100471.27 | I32: FY27 取季度合计；FY28 ＝ 情形设定增速；FY29–32 ＝ 情形增速 + 控制台「长期增速平移」
A33: 收入增速 YoY | B33: =B32/'00-三表与联动'!F28-1 -> 1.429869 | C33: =C32/B32-1 -> 0.18 | D33: =D32/C32-1 -> 0.17 | E33: =E32/D32-1 -> 0.16 | F33: =F32/E32-1 -> 0.12 | G33: =G32/F32-1 -> 0.1 | H33: =$B$211 -> 0.035 | I33: 逐年同比。FY26 实际为 +175%
A34: 毛利率 | B34: =F16/F13 -> 0.84819309 | C34: =MAX(0.05,MIN(0.92,0.8+$B$193)) -> 0.8 | D34: =MAX(0.05,MIN(0.92,0.8+$B$193)) -> 0.8 | E34: =MAX(0.05,MIN(0.92,0.8+$B$193)) -> 0.8 | F34: =MAX(0.05,MIN(0.92,0.78+$B$193)) -> 0.78 | G34: =$B$195 -> 0.76 | H34: =G34 -> 0.76 | I34: 情形设定的年度毛利率 + 控制台「毛利率平移」；FY32 直接取控制台「终局毛利率」
A35: 毛利 | B35: =B32*B34 -> 41731.089 | C35: =C32*C34 -> 46444.787 | D35: =D32*D34 -> 54340.401 | E35: =E32*E34 -> 63034.865 | F35: =F32*F34 -> 68834.073 | G35: =G32*G34 -> 73776.006 | H35: =H32*H34 -> 76358.167 | I35: ＝ 收入 × 毛利率
A36: 营业费用 | B36: =B32*$B$199 -> 2459.9993 | C36: =C32*$B$199 -> 2902.7992 | D36: =D32*$B$199 -> 3396.2751 | E36: =E32*$B$199 -> 3939.6791 | F36: =F32*$B$199 -> 4412.4406 | G36: =G32*$B$199 -> 4853.6846 | H36: =H32*$B$199 -> 5023.5636 | I36: ＝ 收入 × 控制台「营业费用率」
A37: 营业利润 EBIT | B37: =B35-B36 -> 39271.089 | C37: =C35-C36 -> 43541.988 | D37: =D35-D36 -> 50944.126 | E37: =E35-E36 -> 59095.186 | F37: =F35-F36 -> 64421.632 | G37: =G35-G36 -> 68922.322 | H37: =H35-H36 -> 71334.603 | I37: ＝ 毛利 − 营业费用
A38: 营业利润率 | B38: =B37/B32 -> 0.79819309 | C38: =C37/C32 -> 0.75 | D38: =D37/D32 -> 0.75 | E38: =E37/E32 -> 0.75 | F38: =F37/F32 -> 0.73 | G38: =G37/G32 -> 0.71 | H38: =H37/H32 -> 0.71 | I38: ＝ EBIT ÷ 收入。可与投资者日目标「约 75%」对照
A39: 税后经营利润 NOPAT | B39: =B37*(1-$B$201) -> 33380.426 | C39: =C37*(1-$B$201) -> 37010.69 | D39: =D37*(1-$B$201) -> 43302.507 | E39: =E37*(1-$B$201) -> 50230.908 | F39: =F37*(1-$B$201) -> 54758.388 | G39: =G37*(1-$B$201) -> 58583.974 | H39: =H37*(1-$B$201) -> 60634.413 | I39: ＝ EBIT ×(1 − 有效税率)
A40: ＋ 折旧摊销 D&A | B40: =B32*0.0074 -> 364.0799 | C40: =C32*0.0074 -> 429.61428 | D40: =D32*0.0074 -> 502.64871 | E40: =E32*0.0074 -> 583.07251 | F40: =F32*0.0074 -> 653.04121 | G40: =G32*0.0074 -> 718.34533 | H40: =H32*0.0074 -> 743.48741 | I40: ＝ 收入 × 0.74%
A41: − 自有资本开支 | B41: =-B32*$B$203 -> -836.39977 | C41: =-C32*$B$203 -> -986.95173 | D41: =-D32*$B$203 -> -1154.7335 | E41: =-E32*$B$203 -> -1339.4909 | F41: =-F32*$B$203 -> -1500.2298 | G41: =-G32*$B$203 -> -1650.2528 | H41: =-H32*$B$203 -> -1708.0116 | I41: ＝ 收入 × 控制台「自有资本开支率」
A42: − Flash Ventures 净投入 | B42: =-B32*$B$205 -> -1377.5996 | C42: =-C32*$B$205 -> -1625.5676 | D42: =-D32*$B$205 -> -1901.914 | E42: =-E32*$B$205 -> -2206.2203 | F42: =-F32*$B$205 -> -2470.9667 | G42: =-G32*$B$205 -> -2718.0634 | H42: =-H32*$B$205 -> -2813.1956 | I42: ＝ 收入 × 控制台「FV 净投入率」
A43: 营运资本余额 | B43: =B32*$B$207 -> 7871.9979 | C43: =C32*$B$207 -> 9288.9575 | D43: =D32*$B$207 -> 10868.08 | E43: =E32*$B$207 -> 12606.973 | F43: =F32*$B$207 -> 14119.81 | G43: =G32*$B$207 -> 15531.791 | H43: =H32*$B$207 -> 16075.404 | I43: ＝ 控制台「营运资本占年化收入比」× 当年收入。期初取 FY26 Q4 年化收入 × 同一比例
...
