Workbook

Sheet 00-Overview
A1: The Arithmetic of the Gap · Memory Supply–Demand Model
A2: v4.2 Recalibrated Edition | DRAM / NAND / HBM | flow basis (growth gap) + level basis (horizontal adequacy, externally anchored) | data cut-off 2026-09-30 (Micron FQ4 FY26) | amber = new in v4.0, lavender = new or corrected in v4.1, mint = recalibrated in v4.2 (sheet 10 lists every change)
A3: ▲ v4.2 (2026-10-01): recalibrated to Micron's FQ4 FY26 guidance on sheet 11 — 2027 DRAM supply and demand raised together, 2028 capacity moved later on Micron's fab calendar, NAND put on Micron's path. Set sheet 11's master switch to 0 and v4.1 returns cell for cell.
A4: How to use this workbook — read this first
A5: This workbook is the computable version of The Arithmetic of the Gap. Every number is a live formula. Sheets 01 and 02 each carry a PARAMETER CONSOLE at the bottom: drag a slider and the whole sheet and every chart recalculates. Sheet 06 carries another console holding the three v4.0 corrections. This is a framework whose parameters you can replace and recompute — not a forecast. ▲ v4.1: sheet 09 carries one more console (inventory coverage and destination, the HBM penalty path, the stock convention, the external anchor) together with the level-basis probabilities and the external calibration, so console blocks sit on sheets 01, 02, 06 and 09; sheet 10 is the change log. ▲ v4.2: sheet 11 holds the recalibration console (a master switch, six levers and five B-grade switches that default to off), the map of the 51 inputs it acts on, the checks against Micron's guidance and the v4.1 → v4.2 headline comparison.
A6: Blue text | B6: Editable input cell (slider link cells can also be typed into directly)
A7: Black text | B7: Formula output — do not overwrite
A8: Green text | B8: Cross-sheet reference
A9: Yellow fill | B9: Key assumption / current console value — the model is most sensitive to these
A10: Pink fill | B10: Model defect or basis risk found in the audit
A11: Amber fill | B11: Added or revised in v4.0 (2026-09-08) — new relative to the v3.0 workbook
A12: Lavender fill | B12: Added or corrected in v4.1 (2026-09-28) — sheet 09 holds the new levers and checks, sheet 10 lists every change
A13: 01 The two bit-supply formulas: everything starts here
A14: DRAM | B14: Effective bits = wafer starts × net good die per wafer × bits per die × yield × (1 − HBM wafer penalty)
B15: Growth form (used by this model): bit growth = (1 + wafer capacity growth) × (1 + node bit uplift) × (1 − HBM crowd-out) − 1
A16: NAND | B16: Effective bits = wafer starts × die per wafer × layer count × bits per cell × yield
B17: Growth form (used by this model): bit growth = (1 + wafer capacity growth) × (1 + layer uplift) × (1 + QLC mix uplift) − 1
A18: ★ The whole difference sits in this line: NAND has two levers that add bits without new wafer starts (layer stacking 232 → 400+ = +72%, TLC → QLC = +33%, 2.29× in theory when compounded), while DRAM's node steps add far less and HBM takes wafers away. ▲ v4.1: the NAND levers are not free — each layer step adds process steps (SK hynix 321-layer: +44% bits per wafer, +30% process steps), so they need tools and cleanroom space. That is the source of every conclusion below — the same demand meeting two different supply elasticities must produce two price paths.
A20: 02 Four layers of 'gap': which one this model computes
A21: In the market the words 'memory gap' point to at least four different things whose values differ by up to 20×. Mixing them up is the root of most misreadings.
A22: Layer | B22: Basis | C22: Definition | F22: 2026 value | H22: How this model uses it
A23: ① | B23: LATENT | C23: What customers want but cannot buy (quota method). Micron: able to supply only 50%–2/3 of key-customer demand; buyers receive 60–70% of what they request. Known distortion: customers know they will be cut, so they systematically over-request. | F23: −30% ~ −40% | H23: Upper-bound reference, not used
A24: ② | B24: STOCK | C24: Cumulative horizontal gap under an unconstrained-demand assumption. The v2.0 basis. Narrower than ① (over-requests removed), wider than ③ (demand destruction not removed). | F24: −13.6% (med. −14.6%) | H24: ★ Primary basis through v4.0; in v4.1 the level headline is anchored externally (sheet 09 [C])
A25: ③ | B25: CLEARED | C25: The residual gap actually transacted after prices have risen and part of demand has been priced out. TrendForce's published 'sufficiency ratio' is this one. | F25: −1% ~ −2% | H25: External benchmark
A26: ④ | B26: FLOW | C26: The annual rate of change of the gap — the first derivative of ②. The v1.0 basis. It tells you whether the gap is widening or narrowing, not how big it is. | F26: −9.1% | H26: ★ Secondary basis of this model
A27: Chain of logic: ① latent −(30~40)% → [strip customer over-requests] → ② stock −13.6% (median −14.6%) → [strip the consumer-electronics demand priced out: handsets −15~20%, notebooks −9.4% (TrendForce 9/4; −14.8% from March to August)] → ③ cleared −(1~2)%. ④ is not on this chain — it is the first derivative of ②.
A29: 03 Inventory: a physical signal, no longer the anchor of the level ▲ rewritten in v4.0, revised in v4.1
A30: Point in time | B30: Inventory weeks | C30: Note | G30: Implication
A31: Late 2024 | B31: 15 | C31: TrendForce (via Reuters): 13–17 weeks, midpoint used. ▲ v4.1: replaces '31 weeks in early 2023', which could not be traced to the series behind the 3.3-week reading.
A32: End 2025 Q3 | B32: 3.3 | C32: Matched the 2018 super-cycle low; SK hynix and Micron roughly 2 weeks each. | G32: Drawdown from late 2024 ≈ 11.7 weeks (9.7–13.7) ≈ 22% of a year's demand (19–26%). ▲ v4.1: was 27.7 weeks = 53% from the untraceable 31-week start.
A33: Nov 2025 (SK hynix DRAM) | B33: 2 | C33: Korean press. Added in v4.0 — fills the gap between the 3.3-week and the sub-10-day readings.
A34: July 2026 | B34: 4 | C34: Had recovered slightly off the bottom (3–5 week range, midpoint taken).
A35: 2026 Q3 | B35: 1.43 | C35: ★ < 10 days. KB Securities, 2026-09-07, head of research Kim Dong-won. This is the single reading that changes the v4.0 conclusion. | G35: ="Gross 4.9% of 2026 supply released at Samsung + SK hynix; ▲ v4.1: "&SUBSTITUTE(TEXT('09-v4.1-Corrections'!$B$17,"0.0%"),"-","−")&" effective after coverage and the share consumed (φ)" -> Gross 4.9% of 2026 supply released at Samsung + SK hynix; ▲ v4.1: 1.6% effective after coverage and the share consumed (φ)
A36: Industry 'healthy' | B36: 5.35 | C36: 30–45 days = 4.3–6.4 weeks (supply-chain benchmark cited by KB). Added in v4.0.
A37: 'Normal' used by the model | B37: ='01-DRAM-Model'!$B$10 -> 6 | C37: Industry long-run mean, linked to sheet 01 row 10 (v4.0 showed 8 here; the model uses 6). ★ The most fragile parameter behind the ② start point. | G37: Feeds only the reference start point (01 row 13). Gap in use: 01 row 14 slider; restock: typed in 01!B111.
A38: ★★ v4.0: since late 2024 the market has run short without running out because it was eating inventory — from 13–17 weeks down to under 1.5 (▲ v4.1: the 31 weeks of early 2023 quoted before could not be traced to the same series). The buffer is now gone, and the last leg of that drawdown (≈2.57 weeks between July 2026 and Q3 2026) means about 4.9% of 2026 shipments were released from stock rather than produced. From 2027 shipments can only come from production. That single accounting fact, not any new demand datapoint, is what moves the model. ▲ v4.1: two qualifications. The drawdown is a two-supplier reading (about 64% of revenue), and TrendForce reports US CSPs building buffer stock and mobile DRAM buyers holding 12–14 weeks — bits moved onto customer shelves inflate 2026 purchases by the same amount and do not tighten 2027. Sheet 09 carries both as sliders; at the defaults the effective release is about 1.6% of supply, not 4.9%.
A40: 04 Headline results (every figure links live to sheets 01 / 02 / 06)
A41: Product | B41: Basis | C41: 2025 start | D41: 2026 | E41: 2027 | F41: 2028 | G41: Trough year | H41: Filled within three years?
A42: DRAM | B42: ④ Flow: supply − demand growth | C42: — | D42: ='01-DRAM-Model'!D53 -> -0.091210969 | E42: ='01-DRAM-Model'!E53 -> -0.038138274 | F42: ='01-DRAM-Model'!F53 -> 0.072406671 | G42: =CHOOSE(MATCH(MIN(D42:F42),D42:F42,0),"2026","2027","2028") -> 2026 | H42: =IF(D42>0,"Growth gap positive from 2026",IF(E42>0,"Growth gap turns positive in 2027",IF(F42>0,"Growth gap turns positive in 2028","Growth gap negative through 2028"))) -> Growth gap turns positive in 2028
A43: DRAM | B43: ② Stock: horizontal adequacy | C43: ='01-DRAM-Model'!D64 -> -0.07 | D43: ='01-DRAM-Model'!E64 -> -0.13606178 | E43: ='01-DRAM-Model'!F64 -> -0.15682753 | F43: ='01-DRAM-Model'!G64 -> -0.084124503 | G43: =CHOOSE(MATCH(MIN(C43:F43),C43:F43,0),"2025","2026","2027","2028") -> 2027 | H43: =IF(D43>=0,"Filled in 2026",IF(E43>=0,"Weighted: filled in 2027",IF(F43>=0,"Weighted: filled in 2028","Weighted: still short in 2028")))&IF('01-DRAM-Model'!G65>=0,"; median filled by 2028","; median still short in 2028") -> Weighted: still short in 2028; median still short in 2028
...

Sheet 01-DRAM-Model
A1: 01 · DRAM supply–demand model
A2: Five scenarios × three years | flow basis (growth gap) + stock basis (horizontal adequacy) | ▼ every parameter is driven by the [K] PARAMETER CONSOLE at the bottom of this sheet | amber rows are v4.0 additions | lavender = v4.1 | mint = v4.2 (the 2027–28 inputs link to sheet 11)
A4: [A] Global assumptions (values come from console [K] below — drag a slider to change them)
A5: Parameter | B5: Current value | C5: Unit | D5: Note
A6: HBM wafer penalty · 2025–2026 (×) | B6: =$B$143 -> 2.8 | C6: × | D6: 2.8×: TrendForce's own series imply 2.85–2.87× (HBM wafer share vs bit share, if both are on the top-three basis; about 2.2–2.3× if the bit shares are global). Micron uses ~3:1 for HBM3E and says the ratio rises with every generation; KB's '1 HBM4 wafer = 3 conventional wafers' repeats Micron's figure, so it is consistent with the base rather than an independent confirmation. ▲ v4.1: from 2027 the engine uses the path on sheet 09 rows 18–20.
A7: 8-high HBM4 penalty relief from 2027 (×) | B7: ='06-Inventory-Burn-v4'!$B$10 -> -0.3 | C7: × | D7: ▲ v4.0, revised in v4.1. NVIDIA has asked Samsung and SK hynix for a higher 8-high mix on Vera Rubin, and for HBM4E to drop to 8-high for Rubin Ultra. HBM4 base dies are made at logic foundries, so only the stacking-yield gain remains: about −0.3× at a per-layer yield of 0.975 (v4.0: −0.2× net of a −3.7% base-die dilution). Full arithmetic on sheet 07.
A8: HBM wafer penalty · 2027 (×) · v4.1 path | B8: ='09-v4.1-Corrections'!$B$19 -> 3 | C8: × | D8: ="▲ v4.1: base "&TEXT($B$6,"0.00")&"×"&" + trade-ratio step "&SUBSTITUTE(TEXT('09-v4.1-Corrections'!$B$11,"+0.00;-0.00;0.00"),"-","−")&" + 8-high relief "&SUBSTITUTE(TEXT($B$7,"+0.00;-0.00;0.00"),"-","−")&" = "&TEXT($B$8,"0.00")&"×"&" in 2027 and "&TEXT('09-v4.1-Corrections'!$B$20,"0.00")&"×"&" in 2028 (sheet 09 rows 18–20). Used by the sheet 06 engine only — the main grid below stays on the constant row 6 penalty so the v3.0 results remain reproducible." -> ▲ v4.1: base 2.80× + trade-ratio step +0.50 + 8-high relief −0.30 = 3.00× in 2027 and 3.30× in 2028 (sheet 09 rows 18–20). Used by the sheet 06 engine only — the main grid below stays on the constant row 6 penalty so the v3.0 results remain reproducible.
A9: HBM basis correction switch | B9: =$B$145 -> 1 | C9: 0/1 | D9: ★ Audit finding (A, item 4): TrendForce's 18/22/30% is a top-three-supplier basis; the model applied it to a global basis that includes CXMT. Set to 1 to enable the CXMT dilution correction.
A10: 'Normal' inventory (weeks) | B10: 6 | C10: weeks | D10: Industry long-run mean. Feeds the reference start point in row 13 only; the start gap in use is the console slider (row 14) and restock is typed in B111.
A11: Healthy finished-goods inventory (weeks) | B11: 5.35 | C11: weeks | D11: ▲ NEW in v4.0. 30–45 days = 4.3–6.4 weeks, the supply-chain benchmark quoted by KB Securities; 5.35 is the midpoint. Shown for reference — on this basis the start gap would be −7.5% rather than −8.8% (row 13, 6-week normal).
A12: Latest supplier inventory (weeks) | B12: 1.43 | C12: weeks | D12: ▲ REVISED in v4.0: was 3.3 weeks end-2025Q3 (TrendForce via Astute Group; also UncoverAlpha). KB Securities puts Samsung and SK hynix below 10 days in 2026 Q3 = 1.43 weeks.
A13: Inventory-implied start point (reference) | B13: =-($B$10-$B$12)/52 -> -0.087884615 | C13: % | D13: ="Formula: −(normal − actual) ÷ 52. With the v4.0 reading this is "&SUBSTITUTE(TEXT(B13,"0.0%"),"-","−")&" against the "&SUBSTITUTE(TEXT(B10,"0"),"-","−")&"-week normal in row 10, or −7.5% against the 4.3–6.4 week industry benchmark in row 11. Reference only — the model uses the row below." -> Formula: −(normal − actual) ÷ 52. With the v4.0 reading this is −8.8% against the 6-week normal in row 10, or −7.5% against the 4.3–6.4 week industry benchmark in row 11. Reference only — the model uses the row below.
A14: 2025 start gap (value used) | B14: =$B$144 -> -0.07 | C14: % | D14: Driven by the console slider. ★ Audit finding (A, item 2): this is a stock (inventory weeks) being fed into a recursion that is a flow ratio — a dimensional mismatch. See sheet 00 section 07 and block [H] below.
A17: [B] Main model: five scenarios × three years (blue on the left = raw inputs; pink on the right = HBM basis-corrected comparison) ▲ v4.2: the mint 2027–28 inputs (wafer growth, node uplift, HBM share, demand) link to sheet 11: v4.1 value + recalibration.
A18: Scenario | B18: Year | C18: Wafer capacity growth | D18: Node bit uplift | E18: HBM wafer share (top-3 basis) | F18: CXMT wafer share | G18: HBM share (adopted basis) | H18: HBM-equivalent bit capacity | I18: HBM marginal drag | J18: Supply bit growth | K18: Demand growth (unconstrained) | L18: ④ Growth gap (flow basis) | M18: ② Horizontal adequacy (stock basis) | O18: Corrected HBM share | P18: Corrected equiv. bit capacity | Q18: Corrected HBM drag | R18: Corrected supply bit growth | S18: Corrected growth gap (flow) | T18: Corrected horizontal gap (stock)
A19: S1 Extreme tightness | B19: 2025 (start) | C19: — | D19: — | E19: 0.18 | F19: 0.142 | G19: =IF($B$9=1,E19*(1-F19),E19) -> 0.15444 | H19: =(1-G19)+G19/$B$6 -> 0.90071714 | I19: — | J19: — | K19: — | L19: — | M19: =$B$14 -> -0.07 | O19: =E19*(1-F19) -> 0.15444 | P19: =(1-O19)+O19/$B$6 -> 0.90071714 | Q19: — | R19: — | S19: — | T19: =$B$14 -> -0.07
B20: 2026A | C20: 0.07 | D20: 0.13 | E20: 0.22 | F20: 0.171 | G20: =IF($B$9=1,MAX(0,MIN(0.95,E20+$B$148))*(1-F20),MAX(0,MIN(0.95,E20+$B$148))) -> 0.18238 | H20: =(1-G20)+G20/$B$6 -> 0.88275571 | I20: =H20/H19-1 -> -0.019941253 | J20: =(1+C20+$B$146)*(1+D20+$B$147)*(1+I20)-1 -> 0.18498903 | K20: 0.3 | L20: =J20-(K20+$B$149) -> -0.12501097 | M20: =(1+M19)*(1+J20)/(1+K20+$B$149)-1 -> -0.15874825 | O20: =MAX(0,MIN(0.95,E20+$B$148))*(1-F20) -> 0.18238 | P20: =(1-O20)+O20/$B$6 -> 0.88275571 | Q20: =P20/P19-1 -> -0.019941253 | R20: =(1+C20+$B$146)*(1+D20+$B$147)*(1+Q20)-1 -> 0.18498903 | S20: =R20-(K20+$B$149) -> -0.12501097 | T20: =(1+T19)*(1+R20)/(1+K20+$B$149)-1 -> -0.15874825
B21: 2027 | C21: ='11-v4.2-Recalibration'!$D$28 -> 0.11 | D21: ='11-v4.2-Recalibration'!$F$28 -> 0.15 | E21: ='11-v4.2-Recalibration'!$H$28 -> 0.34 | F21: 0.181 | G21: =IF($B$9=1,MAX(0,MIN(0.95,E21+$B$148))*(1-F21),MAX(0,MIN(0.95,E21+$B$148))) -> 0.27846 | H21: =(1-G21)+G21/$B$6 -> 0.82099 | I21: =H21/H20-1 -> -0.069969204 | J21: =(1+C21+$B$146)*(1+D21+$B$147)*(1+I21)-1 -> 0.18718431 | K21: ='11-v4.2-Recalibration'!$J$28 -> 0.38 | L21: =J21-(K21+$B$149) -> -0.20281569 | M21: =(1+M20)*(1+J21)/(1+K21+$B$149)-1 -> -0.28149577 | O21: =MAX(0,MIN(0.95,E21+$B$148))*(1-F21) -> 0.27846 | P21: =(1-O21)+O21/$B$6 -> 0.82099 | Q21: =P21/P20-1 -> -0.069969204 | R21: =(1+C21+$B$146)*(1+D21+$B$147)*(1+Q21)-1 -> 0.18718431 | S21: =R21-(K21+$B$149) -> -0.20281569 | T21: =(1+T20)*(1+R21)/(1+K21+$B$149)-1 -> -0.28149577
B22: 2028 | C22: ='11-v4.2-Recalibration'!$D$33 -> 0.08 | D22: 0.1 | E22: ='11-v4.2-Recalibration'!$H$33 -> 0.4 | F22: 0.185 | G22: =IF($B$9=1,MAX(0,MIN(0.95,E22+$B$148))*(1-F22),MAX(0,MIN(0.95,E22+$B$148))) -> 0.326 | H22: =(1-G22)+G22/$B$6 -> 0.79042857 | I22: =H22/H21-1 -> -0.037225092 | J22: =(1+C22+$B$146)*(1+D22+$B$147)*(1+I22)-1 -> 0.14377659 | K22: 0.28 | L22: =J22-(K22+$B$149) -> -0.14622341 | M22: =(1+M21)*(1+J22)/(1+K22+$B$149)-1 -> -0.36293928 | O22: =MAX(0,MIN(0.95,E22+$B$148))*(1-F22) -> 0.326 | P22: =(1-O22)+O22/$B$6 -> 0.79042857 | Q22: =P22/P21-1 -> -0.037225092 | R22: =(1+C22+$B$146)*(1+D22+$B$147)*(1+Q22)-1 -> 0.14377659 | S22: =R22-(K22+$B$149) -> -0.14622341 | T22: =(1+T21)*(1+R22)/(1+K22+$B$149)-1 -> -0.36293928
A23: S1 Extreme tightness (probability set in console [K]): AI capex keeps being revised up; HBM wafer share pushes to 40%; Rubin Ultra delivers 384GB per GPU; the consumer end is already on the floor and stops deteriorating. Never turns positive in three years.
A24: S2 Base case | B24: 2025 (start) | C24: — | D24: — | E24: 0.18 | F24: 0.142 | G24: =IF($B$9=1,E24*(1-F24),E24) -> 0.15444 | H24: =(1-G24)+G24/$B$6 -> 0.90071714 | I24: — | J24: — | K24: — | L24: — | M24: =$B$14 -> -0.07 | O24: =E24*(1-F24) -> 0.15444 | P24: =(1-O24)+O24/$B$6 -> 0.90071714 | Q24: — | R24: — | S24: — | T24: =$B$14 -> -0.07
B25: 2026A | C25: 0.07 | D25: 0.13 | E25: 0.22 | F25: 0.171 | G25: =IF($B$9=1,MAX(0,MIN(0.95,E25+$B$148))*(1-F25),MAX(0,MIN(0.95,E25+$B$148))) -> 0.18238 | H25: =(1-G25)+G25/$B$6 -> 0.88275571 | I25: =H25/H24-1 -> -0.019941253 | J25: =(1+C25+$B$146)*(1+D25+$B$147)*(1+I25)-1 -> 0.18498903 | K25: 0.28 | L25: =J25-(K25+$B$149) -> -0.10501097 | M25: =(1+M24)*(1+J25)/(1+K25+$B$149)-1 -> -0.14570558 | O25: =MAX(0,MIN(0.95,E25+$B$148))*(1-F25) -> 0.18238 | P25: =(1-O25)+O25/$B$6 -> 0.88275571 | Q25: =P25/P24-1 -> -0.019941253 | R25: =(1+C25+$B$146)*(1+D25+$B$147)*(1+Q25)-1 -> 0.18498903 | S25: =R25-(K25+$B$149) -> -0.10501097 | T25: =(1+T24)*(1+R25)/(1+K25+$B$149)-1 -> -0.14570558
B26: 2027 | C26: ='11-v4.2-Recalibration'!$D$29 -> 0.12 | D26: ='11-v4.2-Recalibration'!$F$29 -> 0.15 | E26: ='11-v4.2-Recalibration'!$H$29 -> 0.3 | F26: 0.181 | G26: =IF($B$9=1,MAX(0,MIN(0.95,E26+$B$148))*(1-F26),MAX(0,MIN(0.95,E26+$B$148))) -> 0.2457 | H26: =(1-G26)+G26/$B$6 -> 0.84205 | I26: =H26/H25-1 -> -0.046112094 | J26: =(1+C26+$B$146)*(1+D26+$B$147)*(1+I26)-1 -> 0.22860762 | K26: ='11-v4.2-Recalibration'!$J$29 -> 0.32 | L26: =J26-(K26+$B$149) -> -0.10139238 | M26: =(1+M25)*(1+J26)/(1+K26+$B$149)-1 -> -0.21083261 | O26: =MAX(0,MIN(0.95,E26+$B$148))*(1-F26) -> 0.2457 | P26: =(1-O26)+O26/$B$6 -> 0.84205 | Q26: =P26/P25-1 -> -0.046112094 | R26: =(1+C26+$B$146)*(1+D26+$B$147)*(1+Q26)-1 -> 0.22860762 | S26: =R26-(K26+$B$149) -> -0.10139238 | T26: =(1+T25)*(1+R26)/(1+K26+$B$149)-1 -> -0.21083261
B27: 2028 | C27: ='11-v4.2-Recalibration'!$D$34 -> 0.12 | D27: 0.11 | E27: ='11-v4.2-Recalibration'!$H$34 -> 0.32 | F27: 0.185 | G27: =IF($B$9=1,MAX(0,MIN(0.95,E27+$B$148))*(1-F27),MAX(0,MIN(0.95,E27+$B$148))) -> 0.2608 | H27: =(1-G27)+G27/$B$6 -> 0.83234286 | I27: =H27/H26-1 -> -0.011527989 | J27: =(1+C27+$B$146)*(1+D27+$B$147)*(1+I27)-1 -> 0.2288684 | K27: 0.24 | L27: =J27-(K27+$B$149) -> -0.021131596 | M27: =(1+M26)*(1+J27)/(1+K27+$B$149)-1 -> -0.2241737 | O27: =MAX(0,MIN(0.95,E27+$B$148))*(1-F27) -> 0.2608 | P27: =(1-O27)+O27/$B$6 -> 0.83234286 | Q27: =P27/P26-1 -> -0.011527989 | R27: =(1+C27+$B$146)*(1+D27+$B$147)*(1+Q27)-1 -> 0.2288684 | S27: =R27-(K27+$B$149) -> -0.021131596 | T27: =(1+T26)*(1+R27)/(1+K27+$B$149)-1 -> -0.2241737
A28: =" S2 Base case (probability set in console [K]): aligned to TrendForce for 2026 (sufficiency −1~−2%). ▲ v4.2: recalibrated to Micron’s FQ4 FY26 guidance — 2027 supply and demand raised together (wafer +2pp, node +3pp, demand +6pp), 2028 wa"&"fer growth cut 4pp because ID2, Hiroshima and Singapore NAND start output only in late 2028. Flow 2028 on this grid: "&SUBSTITUTE(TEXT(L27,"+0.0%;-0.0%;0.0%"),"-","−")&"; on the sheet 06 engine: "&SUBSTITUTE(TEXT('06-Inventory-Burn-v4'!$E$31,"+0.0%;-0.0%;0.0%"),"-","−")&IF('06-Inventory-Burn-v4'!$E$31<0,". The turn moves to about 2029.",". The flow basis turns positive in 2028.") -> S2 Base case (probability set in console [K]): aligned to TrendForce for 2026 (sufficiency −1~−2%). ▲ v4.2: recalibrated to Micron’s FQ4 FY26 guidance — 2027 supply and demand raised together (wafer +2pp, node +3pp, demand +6pp), 2028 wafer growth cut 4pp because ID2, Hiroshima and Singapore NAND start output only in late 2028. Flow 2028 on this grid: −2.1%; on the sheet 06 engine: −3.4%. The turn moves to about 2029.
A29: S3 Relief | B29: 2025 (start) | C29: — | D29: — | E29: 0.18 | F29: 0.142 | G29: =IF($B$9=1,E29*(1-F29),E29) -> 0.15444 | H29: =(1-G29)+G29/$B$6 -> 0.90071714 | I29: — | J29: — | K29: — | L29: — | M29: =$B$14 -> -0.07 | O29: =E29*(1-F29) -> 0.15444 | P29: =(1-O29)+O29/$B$6 -> 0.90071714 | Q29: — | R29: — | S29: — | T29: =$B$14 -> -0.07
B30: 2026A | C30: 0.07 | D30: 0.13 | E30: 0.22 | F30: 0.171 | G30: =IF($B$9=1,MAX(0,MIN(0.95,E30+$B$148))*(1-F30),MAX(0,MIN(0.95,E30+$B$148))) -> 0.18238 | H30: =(1-G30)+G30/$B$6 -> 0.88275571 | I30: =H30/H29-1 -> -0.019941253 | J30: =(1+C30+$B$146)*(1+D30+$B$147)*(1+I30)-1 -> 0.18498903 | K30: 0.26 | L30: =J30-(K30+$B$149) -> -0.085010969 | M30: =(1+M29)*(1+J30)/(1+K30+$B$149)-1 -> -0.13225213 | O30: =MAX(0,MIN(0.95,E30+$B$148))*(1-F30) -> 0.18238 | P30: =(1-O30)+O30/$B$6 -> 0.88275571 | Q30: =P30/P29-1 -> -0.019941253 | R30: =(1+C30+$B$146)*(1+D30+$B$147)*(1+Q30)-1 -> 0.18498903 | S30: =R30-(K30+$B$149) -> -0.085010969 | T30: =(1+T29)*(1+R30)/(1+K30+$B$149)-1 -> -0.13225213
B31: 2027 | C31: ='11-v4.2-Recalibration'!$D$30 -> 0.14 | D31: ='11-v4.2-Recalibration'!$F$30 -> 0.17 | E31: ='11-v4.2-Recalibration'!$H$30 -> 0.28 | F31: 0.181 | G31: =IF($B$9=1,MAX(0,MIN(0.95,E31+$B$148))*(1-F31),MAX(0,MIN(0.95,E31+$B$148))) -> 0.22932 | H31: =(1-G31)+G31/$B$6 -> 0.85258 | I31: =H31/H30-1 -> -0.034183539 | J31: =(1+C31+$B$146)*(1+D31+$B$147)*(1+I31)-1 -> 0.288206 | K31: ='11-v4.2-Recalibration'!$J$30 -> 0.26 | L31: =J31-(K31+$B$149) -> 0.018205996 | M31: =(1+M30)*(1+J31)/(1+K31+$B$149)-1 -> -0.11981259 | O31: =MAX(0,MIN(0.95,E31+$B$148))*(1-F31) -> 0.22932 | P31: =(1-O31)+O31/$B$6 -> 0.85258 | Q31: =P31/P30-1 -> -0.034183539 | R31: =(1+C31+$B$146)*(1+D31+$B$147)*(1+Q31)-1 -> 0.288206 | S31: =R31-(K31+$B$149) -> 0.018205996 | T31: =(1+T30)*(1+R31)/(1+K31+$B$149)-1 -> -0.11981259
B32: 2028 | C32: ='11-v4.2-Recalibration'!$D$35 -> 0.16 | D32: 0.13 | E32: ='11-v4.2-Recalibration'!$H$35 -> 0.26 | F32: 0.185 | G32: =IF($B$9=1,MAX(0,MIN(0.95,E32+$B$148))*(1-F32),MAX(0,MIN(0.95,E32+$B$148))) -> 0.2119 | H32: =(1-G32)+G32/$B$6 -> 0.86377857 | I32: =H32/H31-1 -> 0.013134922 | J32: =(1+C32+$B$146)*(1+D32+$B$147)*(1+I32)-1 -> 0.32801726 | K32: 0.18 | L32: =J32-(K32+$B$149) -> 0.13801726 | M32: =(1+M31)*(1+J32)/(1+K32+$B$149)-1 -> -0.017727672 | O32: =MAX(0,MIN(0.95,E32+$B$148))*(1-F32) -> 0.2119 | P32: =(1-O32)+O32/$B$6 -> 0.86377857 | Q32: =P32/P31-1 -> 0.013134922 | R32: =(1+C32+$B$146)*(1+D32+$B$147)*(1+Q32)-1 -> 0.32801726 | S32: =R32-(K32+$B$149) -> 0.13801726 | T32: =(1+T31)*(1+R32)/(1+K32+$B$149)-1 -> -0.017727672
A33: S3 Relief (probability set in console [K]): the core assumption is that HBM economics reverse — revenue per wafer has already been overtaken by DDR5 64GB RDIMM, wafers flow back to conventional DRAM and the HBM share falls. Combined with new fabs ramping on schedule in 2H27. ⚠ v3.0 flagged this assumption as weakened by the 2026-08-25 forecast of +70~140% HBM contract prices; v4.0 flags it again — this is the scenario the inventory correction flips. ▲ v4.1: with the effective release it no longer flips.
A34: S4 Surplus | B34: 2025 (start) | C34: — | D34: — | E34: 0.18 | F34: 0.142 | G34: =IF($B$9=1,E34*(1-F34),E34) -> 0.15444 | H34: =(1-G34)+G34/$B$6 -> 0.90071714 | I34: — | J34: — | K34: — | L34: — | M34: =$B$14 -> -0.07 | O34: =E34*(1-F34) -> 0.15444 | P34: =(1-O34)+O34/$B$6 -> 0.90071714 | Q34: — | R34: — | S34: — | T34: =$B$14 -> -0.07
B35: 2026A | C35: 0.07 | D35: 0.13 | E35: 0.22 | F35: 0.171 | G35: =IF($B$9=1,MAX(0,MIN(0.95,E35+$B$148))*(1-F35),MAX(0,MIN(0.95,E35+$B$148))) -> 0.18238 | H35: =(1-G35)+G35/$B$6 -> 0.88275571 | I35: =H35/H34-1 -> -0.019941253 | J35: =(1+C35+$B$146)*(1+D35+$B$147)*(1+I35)-1 -> 0.18498903 | K35: 0.24 | L35: =J35-(K35+$B$149) -> -0.065010969 | M35: =(1+M34)*(1+J35)/(1+K35+$B$149)-1 -> -0.11836816 | O35: =MAX(0,MIN(0.95,E35+$B$148))*(1-F35) -> 0.18238 | P35: =(1-O35)+O35/$B$6 -> 0.88275571 | Q35: =P35/P34-1 -> -0.019941253 | R35: =(1+C35+$B$146)*(1+D35+$B$147)*(1+Q35)-1 -> 0.18498903 | S35: =R35-(K35+$B$149) -> -0.065010969 | T35: =(1+T34)*(1+R35)/(1+K35+$B$149)-1 -> -0.11836816
B36: 2027 | C36: ='11-v4.2-Recalibration'!$D$31 -> 0.15 | D36: ='11-v4.2-Recalibration'!$F$31 -> 0.18 | E36: ='11-v4.2-Recalibration'!$H$31 -> 0.24 | F36: 0.181 | G36: =IF($B$9=1,MAX(0,MIN(0.95,E36+$B$148))*(1-F36),MAX(0,MIN(0.95,E36+$B$148))) -> 0.19656 | H36: =(1-G36)+G36/$B$6 -> 0.87364 | I36: =H36/H35-1 -> -0.010326429 | J36: =(1+C36+$B$146)*(1+D36+$B$147)*(1+I36)-1 -> 0.34298704 | K36: ='11-v4.2-Recalibration'!$J$31 -> 0.24 | L36: =J36-(K36+$B$149) -> 0.092987036 | M36: =(1+M35)*(1+J36)/(1+K36+$B$149)-1 -> -0.052783896 | O36: =MAX(0,MIN(0.95,E36+$B$148))*(1-F36) -> 0.19656 | P36: =(1-O36)+O36/$B$6 -> 0.87364 | Q36: =P36/P35-1 -> -0.010326429 | R36: =(1+C36+$B$146)*(1+D36+$B$147)*(1+Q36)-1 -> 0.34298704 | S36: =R36-(K36+$B$149) -> 0.092987036 | T36: =(1+T35)*(1+R36)/(1+K36+$B$149)-1 -> -0.052783896
B37: 2028 | C37: ='11-v4.2-Recalibration'!$D$36 -> 0.2 | D37: 0.15 | E37: ='11-v4.2-Recalibration'!$H$36 -> 0.2 | F37: 0.185 | G37: =IF($B$9=1,MAX(0,MIN(0.95,E37+$B$148))*(1-F37),MAX(0,MIN(0.95,E37+$B$148))) -> 0.163 | H37: =(1-G37)+G37/$B$6 -> 0.89521429 | I37: =H37/H36-1 -> 0.024694709 | J37: =(1+C37+$B$146)*(1+D37+$B$147)*(1+I37)-1 -> 0.4140787 | K37: 0.16 | L37: =J37-(K37+$B$149) -> 0.2440787 | M37: =(1+M36)*(1+J37)/(1+K37+$B$149)-1 -> 0.1448189 | O37: =MAX(0,MIN(0.95,E37+$B$148))*(1-F37) -> 0.163 | P37: =(1-O37)+O37/$B$6 -> 0.89521429 | Q37: =P37/P36-1 -> 0.024694709 | R37: =(1+C37+$B$146)*(1+D37+$B$147)*(1+Q37)-1 -> 0.4140787 | S37: =R37-(K37+$B$149) -> 0.2440787 | T37: =(1+T36)*(1+R37)/(1+K37+$B$149)-1 -> 0.1448189
A38: S4 Surplus (probability set in console [K]): AI capex peaks in 2027; hyperscalers repeat the 2019 sudden stop; CXMT runs full; HBM gives way to DDR5.
A39: S5 Collapse | B39: 2025 (start) | C39: — | D39: — | E39: 0.18 | F39: 0.142 | G39: =IF($B$9=1,E39*(1-F39),E39) -> 0.15444 | H39: =(1-G39)+G39/$B$6 -> 0.90071714 | I39: — | J39: — | K39: — | L39: — | M39: =$B$14 -> -0.07 | O39: =E39*(1-F39) -> 0.15444 | P39: =(1-O39)+O39/$B$6 -> 0.90071714 | Q39: — | R39: — | S39: — | T39: =$B$14 -> -0.07
B40: 2026A | C40: 0.07 | D40: 0.13 | E40: 0.22 | F40: 0.171 | G40: =IF($B$9=1,MAX(0,MIN(0.95,E40+$B$148))*(1-F40),MAX(0,MIN(0.95,E40+$B$148))) -> 0.18238 | H40: =(1-G40)+G40/$B$6 -> 0.88275571 | I40: =H40/H39-1 -> -0.019941253 | J40: =(1+C40+$B$146)*(1+D40+$B$147)*(1+I40)-1 -> 0.18498903 | K40: 0.18 | L40: =J40-(K40+$B$149) -> -0.0050109692 | M40: =(1+M39)*(1+J40)/(1+K40+$B$149)-1 -> -0.073916136 | O40: =MAX(0,MIN(0.95,E40+$B$148))*(1-F40) -> 0.18238 | P40: =(1-O40)+O40/$B$6 -> 0.88275571 | Q40: =P40/P39-1 -> -0.019941253 | R40: =(1+C40+$B$146)*(1+D40+$B$147)*(1+Q40)-1 -> 0.18498903 | S40: =R40-(K40+$B$149) -> -0.0050109692 | T40: =(1+T39)*(1+R40)/(1+K40+$B$149)-1 -> -0.073916136
B41: 2027 | C41: ='11-v4.2-Recalibration'!$D$32 -> 0.16 | D41: ='11-v4.2-Recalibration'!$F$32 -> 0.19 | E41: ='11-v4.2-Recalibration'!$H$32 -> 0.2 | F41: 0.181 | G41: =IF($B$9=1,MAX(0,MIN(0.95,E41+$B$148))*(1-F41),MAX(0,MIN(0.95,E41+$B$148))) -> 0.1638 | H41: =(1-G41)+G41/$B$6 -> 0.8947 | I41: =H41/H40-1 -> 0.013530681 | J41: =(1+C41+$B$146)*(1+D41+$B$147)*(1+I41)-1 -> 0.39907775 | K41: ='11-v4.2-Recalibration'!$J$32 -> 0.18 | L41: =J41-(K41+$B$149) -> 0.20907775 | M41: =(1+M40)*(1+J41)/(1+K41+$B$149)-1 -> 0.088792715 | O41: =MAX(0,MIN(0.95,E41+$B$148))*(1-F41) -> 0.1638 | P41: =(1-O41)+O41/$B$6 -> 0.8947 | Q41: =P41/P40-1 -> 0.013530681 | R41: =(1+C41+$B$146)*(1+D41+$B$147)*(1+Q41)-1 -> 0.39907775 | S41: =R41-(K41+$B$149) -> 0.20907775 | T41: =(1+T40)*(1+R41)/(1+K41+$B$149)-1 -> 0.088792715
B42: 2028 | C42: ='11-v4.2-Recalibration'!$D$37 -> 0.22 | D42: 0.16 | E42: ='11-v4.2-Recalibration'!$H$37 -> 0.15 | F42: 0.185 | G42: =IF($B$9=1,MAX(0,MIN(0.95,E42+$B$148))*(1-F42),MAX(0,MIN(0.95,E42+$B$148))) -> 0.12225 | H42: =(1-G42)+G42/$B$6 -> 0.92141071 | I42: =H42/H41-1 -> 0.029854381 | J42: =(1+C42+$B$146)*(1+D42+$B$147)*(1+I42)-1 -> 0.45744992 | K42: -0.08 | L42: =J42-(K42+$B$149) -> 0.52744992 | M42: =(1+M41)*(1+J42)/(1+K42+$B$149)-1 -> 0.70630199 | O42: =MAX(0,MIN(0.95,E42+$B$148))*(1-F42) -> 0.12225 | P42: =(1-O42)+O42/$B$6 -> 0.92141071 | Q42: =P42/P41-1 -> 0.029854381 | R42: =(1+C42+$B$146)*(1+D42+$B$147)*(1+Q42)-1 -> 0.45744992 | S42: =R42-(K42+$B$149) -> 0.52744992 | T42: =(1+T41)*(1+R42)/(1+K42+$B$149)-1 -> 0.70630199
A43: S5 Collapse (probability set in console [K]): a technical breakthrough sharply cuts memory per unit of compute (KV-cache compression, more aggressive quantisation), or the external financing chain behind AI capex breaks; inventory rebuilds toward the glut levels of 2023.
...

Sheet 02-NAND-Model
A1: 02 · NAND supply–demand model
A2: Four scenarios × three years | the key difference from DRAM: layer stacking and QLC add bits without new wafer starts, though each layer step still needs tools and cleanroom space | ▼ every parameter is driven by the [G] PARAMETER CONSOLE at the bottom | amber rows are v4.0 additions, lavender v4.1 | mint = v4.2 (the 2027–28 inputs link to sheet 11)
A4: [A] Main model: four scenarios × three years ▲ v4.2: the mint 2027–28 layer and demand inputs and the 2028 wafer inputs link to sheet 11.
A5: Scenario | B5: Year | C5: Wafer capacity growth | D5: Layer stacking bit uplift | E5: QLC mix bit uplift | F5: Demand growth (unconstrained) | G5: Supply bit growth | H5: ④ Growth gap (flow basis) | I5: ② Horizontal adequacy (stock basis) | J5: Cross-check: same-year DRAM supply growth | K5: Supply elasticity multiple
A6: N1 Stays tight | B6: 2025 (start) | C6: — | D6: — | E6: — | F6: — | G6: — | H6: — | I6: =$B$76 -> -0.025 | J6: — | K6: —
B7: 2026A | C7: 0 | D7: 0.15 | E7: 0.03 | F7: 0.22 | G7: =(1+C7+$B$78)*(1+D7+$B$79)*(1+E7+$B$80)*(1+$B$77)-1 -> 0.172655 | H7: =G7-(F7+$B$81) -> -0.067345 | I7: =(1+I6)*(1+G7)/(1+F7+$B$81)-1 -> -0.077952722 | J7: ='01-DRAM-Model'!J25 -> 0.18498903 | K7: =IF(J7<=0,"n/a",G7/J7) -> 0.93332561
B8: 2027 | C8: 0.02 | D8: ='11-v4.2-Recalibration'!$F$40 -> 0.14 | E8: 0.04 | F8: ='11-v4.2-Recalibration'!$J$40 -> 0.28 | G8: =(1+C8+$B$78)*(1+D8+$B$79)*(1+E8+$B$80)*(1+$B$77)-1 -> 0.197456 | H8: =G8-(F8+$B$81) -> -0.102544 | I8: =(1+I7)*(1+G8)/(1+F8+$B$81)-1 -> -0.15068381 | J8: ='01-DRAM-Model'!J26 -> 0.22860762 | K8: =IF(J8<=0,"n/a",G8/J8) -> 0.86373323
B9: 2028 | C9: ='11-v4.2-Recalibration'!$D$44 -> 0.05 | D9: ='11-v4.2-Recalibration'!$F$44 -> 0.13 | E9: 0.04 | F9: ='11-v4.2-Recalibration'!$J$44 -> 0.28 | G9: =(1+C9+$B$78)*(1+D9+$B$79)*(1+E9+$B$80)*(1+$B$77)-1 -> 0.222208 | H9: =G9-(F9+$B$81) -> -0.077792 | I9: =(1+I8)*(1+G9)/(1+F9+$B$81)-1 -> -0.20150689 | J9: ='01-DRAM-Model'!J27 -> 0.2288684 | K9: =IF(J9<=0,"n/a",G9/J9) -> 0.97089854
A10: N1 Stays tight (probability set in console [G]): enterprise SSD demand keeps beating expectations, AI data staging and model checkpointing demand explodes; layer progression runs behind plan.
A11: N2 Base case | B11: 2025 (start) | C11: — | D11: — | E11: — | F11: — | G11: — | H11: — | I11: =$B$76 -> -0.025 | J11: — | K11: —
B12: 2026A | C12: 0 | D12: 0.15 | E12: 0.03 | F12: 0.22 | G12: =(1+C12+$B$78)*(1+D12+$B$79)*(1+E12+$B$80)*(1+$B$77)-1 -> 0.172655 | H12: =G12-(F12+$B$81) -> -0.067345 | I12: =(1+I11)*(1+G12)/(1+F12+$B$81)-1 -> -0.077952722 | J12: ='01-DRAM-Model'!J25 -> 0.18498903 | K12: =IF(J12<=0,"n/a",G12/J12) -> 0.93332561
B13: 2027 | C13: 0.04 | D13: ='11-v4.2-Recalibration'!$F$41 -> 0.16 | E13: 0.05 | F13: ='11-v4.2-Recalibration'!$J$41 -> 0.24 | G13: =(1+C13+$B$78)*(1+D13+$B$79)*(1+E13+$B$80)*(1+$B$77)-1 -> 0.25454 | H13: =G13-(F13+$B$81) -> -0.00546 | I13: =(1+I12)*(1+G13)/(1+F13+$B$81)-1 -> -0.08194826 | J13: ='01-DRAM-Model'!J26 -> 0.22860762 | K13: =IF(J13<=0,"n/a",G13/J13) -> 1.1134362
B14: 2028 | C14: ='11-v4.2-Recalibration'!$D$45 -> 0.08 | D14: ='11-v4.2-Recalibration'!$F$45 -> 0.15 | E14: 0.05 | F14: ='11-v4.2-Recalibration'!$J$45 -> 0.22 | G14: =(1+C14+$B$78)*(1+D14+$B$79)*(1+E14+$B$80)*(1+$B$77)-1 -> 0.292025 | H14: =G14-(F14+$B$81) -> 0.052025 | I14: =(1+I13)*(1+G14)/(1+F14+$B$81)-1 -> -0.043430807 | J14: ='01-DRAM-Model'!J27 -> 0.2288684 | K14: =IF(J14<=0,"n/a",G14/J14) -> 1.2759516
A15: N2 Base case (probability set in console [G]): 2026 aligned to TrendForce (gap −4~−5%). SK hynix 321-layer at ~50% of its Korean capacity, Samsung 400+ layer in production, Kioxia BiCS9. ▲ v4.2: recalibrated toward Micron's FQ4 guidance (CY2027–28 industry NAND shipments 'approximately in the mid-20s', supply constrained in both years): layers −2pp and demand +4pp in 2027–28, so N2 no longer turns in 2027. TrendForce's turn in 2H27 now sits in N3 and N4. ⚠ v4.0: KB Securities' view — see block [F].
A16: N3 Turns to surplus | B16: 2025 (start) | C16: — | D16: — | E16: — | F16: — | G16: — | H16: — | I16: =$B$76 -> -0.025 | J16: — | K16: —
B17: 2026A | C17: 0 | D17: 0.15 | E17: 0.03 | F17: 0.2 | G17: =(1+C17+$B$78)*(1+D17+$B$79)*(1+E17+$B$80)*(1+$B$77)-1 -> 0.172655 | H17: =G17-(F17+$B$81) -> -0.047345 | I17: =(1+I16)*(1+G17)/(1+F17+$B$81)-1 -> -0.062837193 | J17: ='01-DRAM-Model'!J25 -> 0.18498903 | K17: =IF(J17<=0,"n/a",G17/J17) -> 0.93332561
B18: 2027 | C18: 0.06 | D18: ='11-v4.2-Recalibration'!$F$42 -> 0.19 | E18: 0.07 | F18: ='11-v4.2-Recalibration'!$J$42 -> 0.2 | G18: =(1+C18+$B$78)*(1+D18+$B$79)*(1+E18+$B$80)*(1+$B$77)-1 -> 0.336965 | H18: =G18-(F18+$B$81) -> 0.116965 | I18: =(1+I17)*(1+G18)/(1+F18+$B$81)-1 -> 0.027011371 | J18: ='01-DRAM-Model'!J26 -> 0.22860762 | K18: =IF(J18<=0,"n/a",G18/J18) -> 1.4739885
B19: 2028 | C19: ='11-v4.2-Recalibration'!$D$46 -> 0.12 | D19: ='11-v4.2-Recalibration'!$F$46 -> 0.18 | E19: 0.06 | F19: ='11-v4.2-Recalibration'!$J$46 -> 0.16 | G19: =(1+C19+$B$78)*(1+D19+$B$79)*(1+E19+$B$80)*(1+$B$77)-1 -> 0.388388 | H19: =G19-(F19+$B$81) -> 0.208388 | I19: =(1+I18)*(1+G19)/(1+F19+$B$81)-1 -> 0.20838158 | J19: ='01-DRAM-Model'!J27 -> 0.2288684 | K19: =IF(J19<=0,"n/a",G19/J19) -> 1.6969926
A20: N3 Turns to surplus (probability set in console [G]): Kioxia/Sandisk's +41% capex converts into capacity; YMTC's third Wuhan fab ramps; the PC replacement cycle ends while mobile demand stays weak; enterprise SSD competition intensifies and caps prices.
A21: N4 Large surplus | B21: 2025 (start) | C21: — | D21: — | E21: — | F21: — | G21: — | H21: — | I21: =$B$76 -> -0.025 | J21: — | K21: —
B22: 2026A | C22: 0 | D22: 0.15 | E22: 0.03 | F22: 0.18 | G22: =(1+C22+$B$78)*(1+D22+$B$79)*(1+E22+$B$80)*(1+$B$77)-1 -> 0.172655 | H22: =G22-(F22+$B$81) -> -0.027345 | I22: =(1+I21)*(1+G22)/(1+F22+$B$81)-1 -> -0.047217813 | J22: ='01-DRAM-Model'!J25 -> 0.18498903 | K22: =IF(J22<=0,"n/a",G22/J22) -> 0.93332561
B23: 2027 | C23: 0.08 | D23: ='11-v4.2-Recalibration'!$F$43 -> 0.22 | E23: 0.08 | F23: ='11-v4.2-Recalibration'!$J$43 -> 0.16 | G23: =(1+C23+$B$78)*(1+D23+$B$79)*(1+E23+$B$80)*(1+$B$77)-1 -> 0.409832 | H23: =G23-(F23+$B$81) -> 0.229832 | I23: =(1+I22)*(1+G23)/(1+F23+$B$81)-1 -> 0.13835832 | J23: ='01-DRAM-Model'!J26 -> 0.22860762 | K23: =IF(J23<=0,"n/a",G23/J23) -> 1.7927311
B24: 2028 | C24: ='11-v4.2-Recalibration'!$D$47 -> 0.16 | D24: ='11-v4.2-Recalibration'!$F$47 -> 0.2 | E24: 0.07 | F24: ='11-v4.2-Recalibration'!$J$47 -> 0.12 | G24: =(1+C24+$B$78)*(1+D24+$B$79)*(1+E24+$B$80)*(1+$B$77)-1 -> 0.4766 | H24: =G24-(F24+$B$81) -> 0.3366 | I24: =(1+I23)*(1+G24)/(1+F24+$B$81)-1 -> 0.47447359 | J24: ='01-DRAM-Model'!J27 -> 0.2288684 | K24: =IF(J24<=0,"n/a",G24/J24) -> 2.0824194
A25: N4 Large surplus (probability set in console [G]): layers and QLC both advance faster than expected while consumer electronics demand stays priced out. This is the risk specific to NAND — supply can keep growing quickly while demand weakens, because adding output needs no new wafer starts (it still needs tools).
A26: ★ The two right-hand columns are new in this workbook: NAND supply growth ÷ same-year DRAM supply growth. They turn the qualitative sentence 'the supply elasticities differ by an order of magnitude' into a number you can track. Note that wafer growth is 0% in 2026 across all four scenarios — NAND's bit growth that year comes from layers and QLC on flat wafer starts. ▲ v4.1: flat wafer starts are not free capacity — SK hynix's 321-layer node adds about 44% memory per wafer but about 30% more process steps (SemiAnalysis IEDM coverage), so migration needs tools and cleanroom space.
A28: [B] Summary 1 · ④ flow basis: supply−demand growth gap
A29: Scenario | B29: Probability | C29: Cumulative prob. | D29: 2026 | E29: 2027 | F29: 2028 | G29: Year the gap turns positive
A30: N1 Stays tight | B30: =$B$83 -> 0.24 | C30: =B30 -> 0.24 | D30: =H7 -> -0.067345 | E30: =H8 -> -0.102544 | F30: =H9 -> -0.077792 | G30: =IF(D30>0,"2026",IF(E30>0,"2027",IF(F30>0,"2028","not within 3 yrs"))) -> not within 3 yrs
A31: N2 Base case | B31: =$B$84 -> 0.44 | C31: =C30+B31 -> 0.68 | D31: =H12 -> -0.067345 | E31: =H13 -> -0.00546 | F31: =H14 -> 0.052025 | G31: =IF(D31>0,"2026",IF(E31>0,"2027",IF(F31>0,"2028","not within 3 yrs"))) -> 2028
A32: N3 Turns to surplus | B32: =$B$85 -> 0.27 | C32: =C31+B32 -> 0.95 | D32: =H17 -> -0.047345 | E32: =H18 -> 0.116965 | F32: =H19 -> 0.208388 | G32: =IF(D32>0,"2026",IF(E32>0,"2027",IF(F32>0,"2028","not within 3 yrs"))) -> 2027
A33: N4 Large surplus | B33: =$B$86 -> 0.05 | C33: =C32+B33 -> 1 | D33: =H22 -> -0.027345 | E33: =H23 -> 0.229832 | F33: =H24 -> 0.3366 | G33: =IF(D33>0,"2026",IF(E33>0,"2027",IF(F33>0,"2028","not within 3 yrs"))) -> 2027
A34: Probability weighted (mean) | B34: =SUM(B30:B33) -> 1 | C34: must = 100% | D34: =SUMPRODUCT($B$30:$B$33,D30:D33) -> -0.059945 | E34: =SUMPRODUCT($B$30:$B$33,E30:E33) -> 0.01605919 | F34: =SUMPRODUCT($B$30:$B$33,F30:F33) -> 0.07731568 | G34: =IF(D34>0,"2026",IF(E34>0,"2027",IF(F34>0,"2028","not within 3 yrs"))) -> 2027
A35: Probability median | B35: =SUM(B30:B33) -> 1 | C35: must = 100% | D35: =INDEX(D30:D33,IFERROR(MATCH(0.5,$C$30:$C$33,1)+1,1)) -> -0.067345 | E35: =INDEX(E30:E33,IFERROR(MATCH(0.5,$C$30:$C$33,1)+1,1)) -> -0.00546 | F35: =INDEX(F30:F33,IFERROR(MATCH(0.5,$C$30:$C$33,1)+1,1)) -> 0.052025 | G35: =IF(D35>0,"2026",IF(E35>0,"2027",IF(F35>0,"2028","not within 3 yrs"))) -> 2028
A37: [C] Summary 2 · ② stock basis: horizontal adequacy
A38: Scenario | B38: Probability | C38: Cumulative prob. | D38: 2025 start | E38: 2026 | F38: 2027 | G38: 2028 | H38: When the gap is filled
A39: N1 Stays tight | B39: =B30 -> 0.24 | C39: =B39 -> 0.24 | D39: =I6 -> -0.025 | E39: =I7 -> -0.077952722 | F39: =I8 -> -0.15068381 | G39: =I9 -> -0.20150689 | H39: =IF(F39>0,"filled in 2027",IF(G39>0,"filled in 2028","not filled in 3 yrs")) -> not filled in 3 yrs
A40: N2 Base case | B40: =B31 -> 0.44 | C40: =C39+B40 -> 0.68 | D40: =I11 -> -0.025 | E40: =I12 -> -0.077952722 | F40: =I13 -> -0.08194826 | G40: =I14 -> -0.043430807 | H40: =IF(F40>0,"filled in 2027",IF(G40>0,"filled in 2028","not filled in 3 yrs")) -> not filled in 3 yrs
A41: N3 Turns to surplus | B41: =B32 -> 0.27 | C41: =C40+B41 -> 0.95 | D41: =I16 -> -0.025 | E41: =I17 -> -0.062837193 | F41: =I18 -> 0.027011371 | G41: =I19 -> 0.20838158 | H41: =IF(F41>0,"filled in 2027",IF(G41>0,"filled in 2028","not filled in 3 yrs")) -> filled in 2027
A42: N4 Large surplus | B42: =B33 -> 0.05 | C42: =C41+B42 -> 1 | D42: =I21 -> -0.025 | E42: =I22 -> -0.047217813 | F42: =I23 -> 0.13835832 | G42: =I24 -> 0.47447359 | H42: =IF(F42>0,"filled in 2027",IF(G42>0,"filled in 2028","not filled in 3 yrs")) -> filled in 2027
A43: Probability weighted (mean) | D43: =SUMPRODUCT($B$39:$B$42,D39:D42) -> -0.025 | E43: =SUMPRODUCT($B$39:$B$42,E39:E42) -> -0.072334783 | F43: =SUMPRODUCT($B$39:$B$42,F39:F42) -> -0.058010363 | G43: =SUMPRODUCT($B$39:$B$42,G39:G42) -> 0.012515497 | H43: =IF(F43>0,"filled in 2027",IF(G43>0,"filled in 2028","not filled in 3 yrs")) -> filled in 2028
...

Sheet 03-Demand-BottomUp
A1: 03 · Bottom-up decomposition of DRAM demand growth
A2: Closes audit finding C, item 5: demand growth is the model's largest driver (1:1 elasticity) yet the reports never derived it | the two bases are benchmarked against two different external datasets
A4: [A] Segment weights and growth assumptions (blue cells are editable; the weights must sum to 100%)
A5: Segment | B5: Share of DRAM bit demand | C5: 2027 unconstrained bit growth | D5: 2027 cleared bit growth | E5: Unconstrained contribution | F5: Cleared contribution | G5: Basis for the weight and the growth rate
A6: HBM | B6: 0.09 | C6: 0.6 | D6: 0.6 | E6: =B6*C6 -> 0.054 | F6: =B6*D6 -> 0.054 | G6: Weight backed out from the model's 22% HBM wafer share and the 3× penalty: (0.22/3) ÷ ((1−0.22) + 0.22/3) = 8.6%. Growth: Rubin carries 288GB of HBM4 per card; AWS adds 2 million GPUs across 2027–28; industry expects HBM shipped bits +50~60% per year.
A7: RDIMM / server | B7: 0.42 | C7: ='11-v4.2-Recalibration'!$J$48 -> 0.3 | D7: 0.3 | E7: =B7*C7 -> 0.126 | F7: =B7*D7 -> 0.126 | G7: TrendForce 2026-08-25: 2027 server DRAM + HBM combined bit supply +27%; 2026-07-09: RDIMM bit supply only +15~20%, 'materially behind server CPU shipment growth'. Demand side taken at 30% because supply is the binding constraint. ▲ v4.2: the 2027 growth links to sheet 11 row 48 (v4.1 30% + switch B5, the agentic CPU-server uplift, default 0).
A8: Handset LPDDR | B8: 0.27 | C8: 0.12 | D8: -0.05 | E8: =B8*C8 -> 0.0324 | F8: =B8*D8 -> -0.0135 | G8: Unconstrained = natural per-handset capacity growth of about 12% a year. Cleared = TrendForce's 2026 handset build −15~20%, falling again in 2027 but more gently.
A9: PC client | B9: 0.13 | C9: 0.12 | D9: -0.05 | E9: =B9*C9 -> 0.0156 | F9: =B9*D9 -> -0.0065 | G9: Cleared basis: TrendForce cut its 2026 global notebook shipment forecast to −14.8% on 2026-03-30 (the −10% the reports quoted looked too optimistic then) and narrowed it to −9.4% on 2026-09-04. ▲ v4.1: date corrected from July and the September revision added; the −5% cleared bit rate is unchanged.
A10: Graphics / consumer / auto / industrial | B10: 0.09 | C10: 0.08 | D10: 0 | E10: =B10*C10 -> 0.0072 | F10: =B10*D10 -> 0 | G10: Residual. GDDR7 and automotive are growing; consumer and industrial are being priced out; combined they are close to flat.
A11: Weighted total | B11: =SUM(B6:B10) -> 1 | C11: — | D11: — | E11: =SUM(E6:E10) -> 0.2352 | F11: =SUM(F6:F10) -> 0.16 | G11: =IF(ABS(B11-1)<0.0001,"✔ Weights sum to 100%; the comparison below is valid.","⚠ Currently "&TEXT(B11,"0.0%")&" — put the weights back to 100%.") -> ✔ Weights sum to 100%; the comparison below is valid.
A13: [B] Three-way comparison: against the model assumption and against external data
A14: Item | B14: 2027 value | C14: Implied gap | D14: External benchmark | H14: Verdict
A15: Model S2 2027 supply bit growth | B15: ='01-DRAM-Model'!J26 -> 0.22860762 | C15: — | D15: TrendForce: server DRAM + HBM combined +27% (a server-only basis runs above the all-in basis; direction consistent) | H15: ✔ consistent
A16: Model S2 2027 demand growth (in use) | B16: ='01-DRAM-Model'!K26+'01-DRAM-Model'!$B$149 -> 0.33 | C16: =B15-B16 -> -0.10139238 | D16: No derivation — the hole audit finding C, item 5 pointed at | H16: △ no basis
A17: This decomposition · unconstrained basis | B17: =E11 -> 0.2352 | C17: =B15-B17 -> -0.0065923768 | D17: Built here. ▲ v4.1: the RDIMM weight is set as the residual of TrendForce's 'HBM + RDIMM = 51% of DRAM bit supply' (51% − 9%), so matching 51% is by construction, not a check. | H17: ="★ about "&SUBSTITUTE(TEXT((B16-B17)*100,"0.0"),"-","−")&"pp below the value in use" -> ★ about 9.5pp below the value in use
A18: This decomposition · cleared basis | B18: =F11 -> 0.16 | C18: =B15-B18 -> 0.068607623 | D18: TrendForce, 'Diverging Memory Market Outlook in 2027': DRAM sufficiency −1%~−2%. This row is a flow × cleared basis, so the two are directly comparable. | H18: open reconciliation item
A20: ="★★ This is the most important addition of v3.0. v2.0 once used NAND's −4.1% to 'validate' TrendForce's −4~−5%, but audit finding A, item 1 showed that to be a pseudo-validation — one free parameter (NAND start −2.0%, no derivation) fitted t"&"o one target. This table instead decomposes five segments first, then sets the two bases against two external datasets: the unconstrained basis gives "&SUBSTITUTE(TEXT(C17,"+0.0%;-0.0%;0.0%"),"-","−")&" (the value in use gives "&SUBSTITUTE(TEXT(C16,"+0.0%;-0.0%;0.0%"),"-","−")&"). ▲ v4.1: the cleared basis gives "&SUBSTITUTE(TEXT(C18,"+0.0%;-0.0%;0.0%"),"-","−")&", which does not reproduce TrendForce's −1~−2% sufficiency — the two differ in basis (a flow here, a level there) and in year, and the write-up withdrew the match. It stays an open reconciliation item." -> ★★ This is the most important addition of v3.0. v2.0 once used NAND's −4.1% to 'validate' TrendForce's −4~−5%, but audit finding A, item 1 showed that to be a pseudo-validation — one free parameter (NAND start −2.0%, no derivation) fitted to one target. This table instead decomposes five segments first, then sets the two bases against two external datasets: the unconstrained basis gives −0.7% (the value in use gives −10.1%). ▲ v4.1: the cleared basis gives +6.9%, which does not reproduce TrendForce's −1~−2% sufficiency — the two differ in basis (a flow here, a level there) and in year, and the write-up withdrew the match. It stays an open reconciliation item.
A22: [C] v3.0 finding (grade A): the start point and the recursion use different denominators
A23: ="Start −9.0% = (normal 8 weeks − actual 3.3 weeks) ÷ 52 — the v3.0 calibration; on the v4.0 reading of 1.43 weeks and the 6-week normal now used the same formula gives "&SUBSTITUTE(TEXT('01-DRAM-Model'!$B$13,"0.0%"),"-","−")&", and the console uses "&SUBSTITUTE(TEXT('01-DRAM-Model'!$B$14,"0.0%"),"-","−")&". Inventory weeks are converted using ACTUAL (cleared) consumption, so the denominator is cleared demand. But the recursion (1+gap_t−1)×(1+supply)÷(1+demand) uses UNCONSTRAINED demand. Two different denominators inside one continued product"&". Consequence: the gap is systematically computed too deep. The table below quantifies the mismatch." -> Start −9.0% = (normal 8 weeks − actual 3.3 weeks) ÷ 52 — the v3.0 calibration; on the v4.0 reading of 1.43 weeks and the 6-week normal now used the same formula gives −8.8%, and the console uses −7.0%. Inventory weeks are converted using ACTUAL (cleared) consumption, so the denominator is cleared demand. But the recursion (1+gap_t−1)×(1+supply)÷(1+demand) uses UNCONSTRAINED demand. Two different denominators inside one continued product. Consequence: the gap is systematically computed too deep. The table below quantifies the mismatch.
A24: Item | B24: Value | C24: Note
A25: Unconstrained demand (this sheet) | B25: =B17 -> 0.2352 | C25: The denominator the recursion uses
A26: Cleared demand (this sheet) | B26: =B18 -> 0.16 | C26: The denominator the start-point calibration implies
A27: Single-year basis difference | B27: =(B25-B26)*100 -> 7.52 | C27: percentage points per year
A28: Three-year cumulative mismatch | B28: =(((1+B25)^3/(1+B26)^3)-1)*100 -> 20.736305 | C28: ="★ This is the main reason the model's stock gap ("&SUBSTITUTE(TEXT('01-DRAM-Model'!$G$65,"0.0%"),"-","−")&" in 2028, base case) runs deeper than any external dataset." -> ★ This is the main reason the model's stock gap (−22.4% in 2028, base case) runs deeper than any external dataset.
A30: Two ways to fix it, mutually exclusive: ① keep the start point at −9.0% but switch the recursion denominator to cleared demand; or ② keep the unconstrained denominator but recalibrate the start point to an inventory gap measured on the unconstrained basis — which would be shallower than −9.0%, since cleared demand is smaller than unconstrained demand. This workbook does not choose for you; it sets both paths side by side in block [B] of sheet 05.
A32: [D] v4.0 addition: two demand-side items this decomposition cannot yet close
A33: Item | B33: What KB Securities says | E33: What this model says | G33: Why they cannot be compared directly
A34: Memory as a share of AI capex | B34: Memory rises from 14% of global AI infrastructure investment in 2025 to 57% in 2027 — a fourfold expansion in two years. Global AI infrastructure investment reaches $1.3tn in 2027, +60% year on year. | E34: DRAM + NAND rise from 47% of major-CSP capex in 2026 to 68% in 2027 (TrendForce 2026-08-25), used on sheet 04 to back out bit demand. | G34: ★ The denominators differ (CSP capex versus global AI infrastructure investment) so the two percentages are not comparable; the direction is the same. Tracking item 8 on sheet 08 is to put them on one basis.
A35: Enterprise SSD (eSSD) bit demand | B35: AI server investment pulls server DDR5 and enterprise SSD together, so the 2027 NAND gap also exceeds 10%. | E35: This sheet models DRAM only; the NAND demand assumption sits on sheet 02 and the v3.0 base case used 18% for 2027. | G35: ★ No independent read on eSSD bit demand has been obtained. This is the single source of the disagreement with KB on NAND and is the highest-priority information gap on the v4.0 tracking list.
A36: Second de-spec event (NVIDIA 8-high) | B36: Not addressed by KB. DigiTimes gives NVIDIA's reason as thermal limits, packaging yield and memory availability under tight supply. | E36: Tracking item 14 in v3.0 said a second de-spec would materially overturn the unconstrained-demand basis. It has now happened. | G36: ★ The motive is two-sided. Supply-driven de-spec (cannot get the parts) does not constitute a real fall in demand — it defers or displaces it. Technical de-spec (heat, power, packaging yield) does. v4.0's treatment: keep the basis, add a physical ceiling — 600kW per rack is that ceiling.
A37: ★ Honest limitation: nothing in this block changes a number in the decomposition above. It is recorded because v4.0's NAND correction is an alignment to someone else's judgement rather than a new measurement, and because the second de-spec puts a physical ceiling on the unconstrained-demand basis that the model still does not enforce anywhere.

Sheet 04-NVDA-Calibration
A1: 04 · External confirmation: NVIDIA FY2027 Q2, TrendForce 8/25 and KB Securities 9/7
A2: The v3.0 data cut-off was 2026-08-24; the v4.0 cut-off is 2026-09-08. Every item below is tagged with which model assumption it strengthens or weakens, and which cell it touches
A4: [A] Six items confirmed by NVIDIA FY27 Q2 (through 2026-07-26)
A5: Confirmed item | B5: Figure / wording | E5: Direction | G5: Which cell it touches | I5: Assessment
A6: Supply and capacity commitments | B6: $119.0bn → $279.0bn; the 10-Q says explicitly 'primarily memory and manufacturing capacity'; by year: FY27 remaining $92.0bn / FY28 $87.0bn / FY29 $88.0bn, collapsing to $6.0bn in FY30 | E6: ★ Strengthens the demand side (2026–28) △ but draws a 2029 boundary | G6: Sheet 01 column K (demand growth) 2026–2028 | I6: The hardest external support the demand assumption has: one company has locked three years of memory volume under binding contracts. But the 93% collapse in FY30 is information too — NVIDIA itself will not commit beyond 2029.
A7: CFO Kress on the earnings call | B7: 'Today's memory scarcity is in large part driven by the AI build-out itself' | E7: ★ Strengthens the demand attribution | G7: Section 03 of sheet 00, the inventory anchor narrative | I7: The largest buyer publicly accepts that the scarcity is of its own making. That rules out the alternative explanation that scarcity is deliberate supplier restraint.
A8: Q3 FY27 gross margin guidance | B8: 74.0%, down 100bp sequentially, principally on memory cost; Grace Blackwell and Vera Rubin systems priced up 15%+ from early 2027 | E8: ★ Confirms the price transmission chain | G8: Whole model (the price mechanism sits outside it) | I8: Memory inflation is now large enough to cost NVIDIA 100bp of gross margin, and NVIDIA's response was to pass it on rather than de-spec. So the 'physical gap → price' transmission was not being blocked by buyer resistance in 2026–27.
A9: Top five cloud vendors' capex | B9: 2026 nearly $800bn → 2027 $1.3tn (+63%) | E9: ★ Strengthens the demand side | G9: Sheet 01 K26 (S2 2027 demand) | I9: ★ Note the basis difference against TrendForce, which puts 2027 CSP capex at +50%. The two differ by 13pp and NVIDIA is the seller.
A10: AWS incremental orders | B10: An additional 2 million GPUs deployed across 2027–2028 (Blackwell Ultra / Rubin / Rubin Ultra) | E10: ★ Strengthens HBM demand | G10: Sheet 03 HBM row (weight 9%, growth 60%) | I10: Rubin carries 288GB of HBM4 per card, so 2 million units is roughly 576PB of incremental HBM4 spread over two years — direct support for the HBM growth assumption on sheet 03.
A11: SOCAMM de-spec (2026-06) | B11: Vera CPU-side SOCAMM 192GB → 96GB; SOCAMM DRAM per rack 55TB → 28TB; rack BOM $7.60m → $6.80m | E11: ✗ Weakens the 'unconstrained demand' assumption | G11: The basis premise behind sheet 03 and sheet 01 column K | I11: ★★ The most important counter-evidence against the model: demand is not price-inelastic. Past a certain price the largest buyer redesigns the demand away. HBM is unaffected (architecturally rigid); conventional DRAM and LPDDR are exposed. ▲ v4.0: the 8-high HBM4 request is the SECOND such event — see sheet 06.
A13: [B] TrendForce 2026-08-25: the structure of CSP capex (published after the v3.0 cut-off)
A14: Metric | C14: 2026 | D14: 2027 | E14: Meaning
A15: CSP total capex growth | C15: 0.98 | D15: 0.5 | E15: NVIDIA's basis puts 2027 at +63%; the two differ by 13pp
A16: DRAM + NAND as a share of CSP capex | C16: 0.47 | D16: 0.68 | E16: ★ Memory is eating two thirds of cloud capex
A17: Server DRAM cumulative contract price increase | C17: 2.7 | D17: — | E17: About +270% across 2026 (2H25 alone was +64%)
A18: Enterprise SSD cumulative contract price increase | C18: 2.35 | D18: — | E18: About +235% across 2026 (2H25 alone was +35%)
A19: HBM contract price increase | C19: — | D19: 1.05 | E19: +70~140% in 2027, midpoint taken. ⚠ Opposite in direction to the v1.0 'HBM economics reversal' assumption
A20: HBM + RDIMM as a share of DRAM bit supply | C20: 0.51 | D20: — | E20: ★ Used to check the segment weights on sheet 03
A21: Server DRAM + HBM bit supply growth | C21: — | D21: 0.27 | E21: 2027; RDIMM alone only +15~20% (TrendForce 7/9)
A23: [C] Backing out memory bit demand from the CSP basis — a cross-check on the model's 2027 demand
A24: Step | C24: Expression | G24: Result | H24: Note
A25: ① CSP memory spend growth 2027 (in money) | C25: (1 + CSP capex growth_27) × memory share_27 ÷ memory share_26 − 1 | G25: =(1+D15)*D16/C16-1 -> 1.1702128 | H25: CSP memory purchasing growth measured in money
A26: ② 2027 blended ASP increase (editable) | C26: Assumption: server DRAM rising quarter on quarter but decelerating, plus HBM +70~140%, blended at 50% | G26: 0.5 | H26: ★ The most sensitive input on this sheet. Enter 40% and bit growth rises to about 55%; enter 60% and it falls to about 36%.
A27: ③ CSP memory bit demand growth | C27: Expression: (1 + ①) ÷ (1 + ②) − 1 | G27: =(1+G25)/(1+G26)-1 -> 0.44680851 | H27: The CSP leg only; excludes handsets, PCs and consumer
A28: ④ Converted to the whole market | C28: CSP weight × ③ + non-CSP weight × non-CSP growth | G28: =('03-Demand-BottomUp'!B6+'03-Demand-BottomUp'!B7)*G27+(1-'03-Demand-BottomUp'!B6-'03-Demand-BottomUp'!B7)*'03-Demand-BottomUp'!C8 -> 0.28667234 | H28: CSP weight = the HBM and RDIMM rows on sheet 03; non-CSP growth borrows the handset unconstrained rate as a proxy
A29: ⑤ Cross-check: the value the model uses | C29: Sheet 01 K26 plus the console demand shift | G29: ='01-DRAM-Model'!K26+'01-DRAM-Model'!$B$149 -> 0.33 | H29: Two routes that share inputs (this back-out reuses sheet 03's 51/49 weights and its 12% handset rate) land at 23.5% and 28.7%. ▲ v4.1: a consistency check, not two confirmations — the blended ASP in row 26 is a free parameter (+80% gives about 16%, +100% about 10%), so this route brackets roughly 10–35%.
A31: ★ How to read it: the value of this section is not a more accurate number but a second route to the one key parameter the model never derived. One route runs low (23.5%), the other high (28.7%), and the value in use sits between them. ▲ v4.1: the two routes share the segment weights and the handset rate, and the memory-share series is DRAM + NAND combined (TrendForce 8/25) while the result is read as DRAM bit demand, so this is a consistency check rather than a validation.
A33: [D] v4.0 addition: KB Securities research note, 2026-09-07 (head of research Kim Dong-won)
A34: 'As of the third quarter, memory inventory at Samsung Electronics and SK hynix has fallen below 10 days. That goes beyond a simple demand recovery — there is a high probability that the absolute supply available is insufficient. Next year's saleable memory volume running out could become reality.' Carried by DigiTimes, Seoul Economic Daily, TechTimes and technetbooks, all dated 2026-09-07.
A35: # | B35: KB's quantification | F35: Impact on this model | I35: How this workbook handles it
A36: ① | B36: 2027 DRAM and NAND bit demand growth will exceed supply growth by more than 10 percentage points | F36: ="Directly comparable with the flow basis. My S2 2027 growth gap is "&SUBSTITUTE(TEXT('01-DRAM-Model'!$L$26,"+0.0%;-0.0%;0.0%"),"-","−")&" on the production basis and "&SUBSTITUTE(TEXT('06-Inventory-Burn-v4'!$G$19,"+0.0%;-0.0%;0.0%"),"-","−")&" with all corrections (v4.2 inputs); KB's figure is 'more than 10 points'." -> Directly comparable with the flow basis. My S2 2027 growth gap is −10.1% on the production basis and −10.1% with all corrections (v4.2 inputs); KB's figure is 'more than 10 points'. | I36: Sheet 09 [D] row 54 sets the v4.1 flow against KB's figure.
A37: ② | B37: (withdrawn in v4.1) 'The 2027 supply gap will exceed 10%' was a misreading of ①: the Korean text says demand growth exceeds supply growth by '10%포인트 이상' — a growth gap in points, not a level. | F37: ="Read as a growth gap, ① is the comparison that matters. On NAND the disagreement is about the growth gap: my N2 base case has 2027 at "&SUBSTITUTE(TEXT('02-NAND-Model'!$H$13,"+0.0%;-0.0%;0.0%"),"-","−")&" before the v4.0 alignment (sheet 02 block [F])." -> Read as a growth gap, ① is the comparison that matters. On NAND the disagreement is about the growth gap: my N2 base case has 2027 at −0.5% before the v4.0 alignment (sheet 02 block [F]). | I37: Sheet 02 block [F] applies the NAND correction with both levers reversible.
A38: ③ | B38: Producing HBM4 consumes three times the wafer capacity of conventional DRAM | F38: ▲ v4.1: consistent with, not independent of, Micron's 3:1 — '1 HBM4 wafer = 3 conventional wafers' is the industry rule of thumb that starts there. Better support for the base comes from TrendForce's own series (implied 2.85–2.87×), and Micron says the ratio rises with HBM4 and HBM4E (sheet 09 rows 11–12). | I38: Sheet 01 row 6 keeps the 2.8× base; the v4.1 path from 2027 is on sheet 09.
A39: ④ | B39: The shortage is not confined to HBM — AI server investment pulls server DDR5 and enterprise SSD at the same time | F39: Consistent with the RDIMM weight on sheet 03; on the NAND side it is the mechanism behind the disagreement in item ②. | I39: Recorded as the top information gap on the sheet 08 tracking list.
A41: Other data published in the same note | C41: Value | E41: Note
